Workbook

Sheet Scores
A1: MCDA Scoring Matrix — Table W.1 (Updated with Final MC)
A2: Blue cells = editable inputs. All scores 0-100, higher = better for Revolut. Results sheet auto-updates.
A4: T = 5 years (base case)
A5: # | B5: Criterion | C5: Dir | D5: Option A | E5: Option B | F5: Option C
A6: C1 | B6: EMV at T=5 | C6: Max | D6: 0 | E6: 100 | F6: 47
A7: C2 | B7: Worst-case downside | C7: Min | D7: 100 | E7: 0 | F7: 59
A8: C3 | B8: UK banking-licence risk | C8: Min | D8: 85 | E8: 20 | F8: 45
A9: C4 | B9: Run-risk crisis exposure | C9: Min | D9: 95 | E9: 20 | F9: 55
A10: C5 | B10: Reversibility | C10: Max | D10: 95 | E10: 10 | F10: 75
A11: C6 | B11: Governance fit (TCE) + GBP opt. | C11: Max | D11: 15 | E11: 55 | F11: 90
A14: T = 7 years (post-crossover: C overtakes B on EMV at 6.1yr)
A15: At T=7, EMV(C)=€23.065m > EMV(B)=€17.643m. C1 and C2 change; C3-C6 unchanged (not horizon-dependent).
A16: # | B16: Criterion | C16: Dir | D16: Option A | E16: Option B | F16: Option C
A17: C1 | B17: EMV at T=7 | C17: Max | D17: 0 | E17: 76 | F17: 100
A18: C2 | B18: Worst-case downside (T=7) | C18: Min | D18: 100 | E18: 0 | F18: 71
A19: C3 | B19: UK banking-licence risk | C19: Min | D19: 85 | E19: 20 | F19: 45
A20: C4 | B20: Run-risk crisis exposure | C20: Min | D20: 95 | E20: 20 | F20: 55
A21: C5 | B21: Reversibility | C21: Max | D21: 95 | E21: 10 | F21: 75
A22: C6 | B22: Governance fit (TCE) + GBP opt. | C22: Max | D22: 15 | E22: 55 | F22: 90

Sheet Weights
A1: Weight Profiles — SWING Elicitation
A2: SWING: rank criteria, top=100, rate others relative, normalise. Edit blue ranks; normalised weights auto-update.
A4: Raw SWING ranks
A5: Criterion | B5: CFO | C5: CRO | D5: Strategy | E5: Balanced
A6: C1: EMV | B6: 100 | C6: 30 | D6: 60 | E6: 100
A7: C2: Downside | B7: 50 | C7: 70 | D7: 30 | E7: 100
A8: C3: UK licence | B8: 15 | C8: 90 | D8: 35 | E8: 100
A9: C4: Run-risk | B9: 10 | C9: 100 | D9: 40 | E9: 100
A10: C5: Reversibility | B10: 25 | C10: 50 | D10: 80 | E10: 100
A11: C6: Governance+GBP | B11: 35 | C11: 25 | D11: 100 | E11: 100
A12: Sum | B12: =SUM(B6:B11) -> 235 | C12: =SUM(C6:C11) -> 365 | D12: =SUM(D6:D11) -> 345 | E12: =SUM(E6:E11) -> 600
A14: Normalised weights
A15: C1: EMV | B15: =B6/B$12 -> 0.42553191 | C15: =C6/C$12 -> 0.082191781 | D15: =D6/D$12 -> 0.17391304 | E15: =E6/E$12 -> 0.16666667
A16: C2: Downside | B16: =B7/B$12 -> 0.21276596 | C16: =C7/C$12 -> 0.19178082 | D16: =D7/D$12 -> 0.086956522 | E16: =E7/E$12 -> 0.16666667
A17: C3: UK licence | B17: =B8/B$12 -> 0.063829787 | C17: =C8/C$12 -> 0.24657534 | D17: =D8/D$12 -> 0.10144928 | E17: =E8/E$12 -> 0.16666667
A18: C4: Run-risk | B18: =B9/B$12 -> 0.042553191 | C18: =C9/C$12 -> 0.2739726 | D18: =D9/D$12 -> 0.11594203 | E18: =E9/E$12 -> 0.16666667
A19: C5: Reversibility | B19: =B10/B$12 -> 0.10638298 | C19: =C10/C$12 -> 0.1369863 | D19: =D10/D$12 -> 0.23188406 | E19: =E10/E$12 -> 0.16666667
A20: C6: Governance+GBP | B20: =B11/B$12 -> 0.14893617 | C20: =C11/C$12 -> 0.068493151 | D20: =D11/D$12 -> 0.28985507 | E20: =E11/E$12 -> 0.16666667
A21: Sum (=1.0000) | B21: =SUM(B15:B20) -> 1 | C21: =SUM(C15:C20) -> 1 | D21: =SUM(D15:D20) -> 1 | E21: =SUM(E15:E20) -> 1

Sheet Results
A1: MCDA Weighted Scores
A2: All values = SUMPRODUCT(weights × scores). Auto-updates from Scores and Weights sheets.
A4: T = 5 years
A5: Profile | B5: Option A | C5: Option B | D5: Option C | E5: Winner | F5: Margin | G5: 2nd
A6: CFO | B6: =SUMPRODUCT(Weights!B15:B20,Scores!D6:D11) -> 43.085106 | C6: =SUMPRODUCT(Weights!B15:B20,Scores!E6:E11) -> 53.93617 | D6: =SUMPRODUCT(Weights!B15:B20,Scores!F6:F11) -> 59.148936 | E6: =INDEX({"A","B","C"},MATCH(MAX(B6:D6),B6:D6,0)) -> C | F6: =MAX(B6:D6)-LARGE(B6:D6,2) -> 5.212766 | G6: =INDEX({"A","B","C"},MATCH(LARGE(B6:D6,2),B6:D6,0)) -> B
A7: CRO | B7: =SUMPRODUCT(Weights!C15:C20,Scores!D6:D11) -> 80.205479 | C7: =SUMPRODUCT(Weights!C15:C20,Scores!E6:E11) -> 23.767123 | D7: =SUMPRODUCT(Weights!C15:C20,Scores!F6:F11) -> 57.780822 | E7: =INDEX({"A","B","C"},MATCH(MAX(B7:D7),B7:D7,0)) -> A | F7: =MAX(B7:D7)-LARGE(B7:D7,2) -> 22.424658 | G7: =INDEX({"A","B","C"},MATCH(LARGE(B7:D7,2),B7:D7,0)) -> C
A8: Strategy | B8: =SUMPRODUCT(Weights!D15:D20,Scores!D6:D11) -> 54.710145 | C8: =SUMPRODUCT(Weights!D15:D20,Scores!E6:E11) -> 40 | D8: =SUMPRODUCT(Weights!D15:D20,Scores!F6:F11) -> 67.724638 | E8: =INDEX({"A","B","C"},MATCH(MAX(B8:D8),B8:D8,0)) -> C | F8: =MAX(B8:D8)-LARGE(B8:D8,2) -> 13.014493 | G8: =INDEX({"A","B","C"},MATCH(LARGE(B8:D8,2),B8:D8,0)) -> A
A9: Balanced | B9: =SUMPRODUCT(Weights!E15:E20,Scores!D6:D11) -> 65 | C9: =SUMPRODUCT(Weights!E15:E20,Scores!E6:E11) -> 34.166667 | D9: =SUMPRODUCT(Weights!E15:E20,Scores!F6:F11) -> 61.833333 | E9: =INDEX({"A","B","C"},MATCH(MAX(B9:D9),B9:D9,0)) -> A | F9: =MAX(B9:D9)-LARGE(B9:D9,2) -> 3.1666667 | G9: =INDEX({"A","B","C"},MATCH(LARGE(B9:D9,2),B9:D9,0)) -> C
A12: T = 7 years
A13: Profile | B13: Option A | C13: Option B | D13: Option C | E13: Winner | F13: Margin | G13: 2nd
A14: CFO | B14: =SUMPRODUCT(Weights!B15:B20,Scores!D17:D22) -> 43.085106 | C14: =SUMPRODUCT(Weights!B15:B20,Scores!E17:E22) -> 43.723404 | D14: =SUMPRODUCT(Weights!B15:B20,Scores!F17:F22) -> 84.255319 | E14: =INDEX({"A","B","C"},MATCH(MAX(B14:D14),B14:D14,0)) -> C | F14: =MAX(B14:D14)-LARGE(B14:D14,2) -> 40.531915 | G14: =INDEX({"A","B","C"},MATCH(LARGE(B14:D14,2),B14:D14,0)) -> B
A15: CRO | B15: =SUMPRODUCT(Weights!C15:C20,Scores!D17:D22) -> 80.205479 | C15: =SUMPRODUCT(Weights!C15:C20,Scores!E17:E22) -> 21.794521 | D15: =SUMPRODUCT(Weights!C15:C20,Scores!F17:F22) -> 64.438356 | E15: =INDEX({"A","B","C"},MATCH(MAX(B15:D15),B15:D15,0)) -> A | F15: =MAX(B15:D15)-LARGE(B15:D15,2) -> 15.767123 | G15: =INDEX({"A","B","C"},MATCH(LARGE(B15:D15,2),B15:D15,0)) -> C
A16: Strategy | B16: =SUMPRODUCT(Weights!D15:D20,Scores!D17:D22) -> 54.710145 | C16: =SUMPRODUCT(Weights!D15:D20,Scores!E17:E22) -> 35.826087 | D16: =SUMPRODUCT(Weights!D15:D20,Scores!F17:F22) -> 77.985507 | E16: =INDEX({"A","B","C"},MATCH(MAX(B16:D16),B16:D16,0)) -> C | F16: =MAX(B16:D16)-LARGE(B16:D16,2) -> 23.275362 | G16: =INDEX({"A","B","C"},MATCH(LARGE(B16:D16,2),B16:D16,0)) -> A
A17: Balanced | B17: =SUMPRODUCT(Weights!E15:E20,Scores!D17:D22) -> 65 | C17: =SUMPRODUCT(Weights!E15:E20,Scores!E17:E22) -> 30.166667 | D17: =SUMPRODUCT(Weights!E15:E20,Scores!F17:F22) -> 72.666667 | E17: =INDEX({"A","B","C"},MATCH(MAX(B17:D17),B17:D17,0)) -> C | F17: =MAX(B17:D17)-LARGE(B17:D17,2) -> 7.6666667 | G17: =INDEX({"A","B","C"},MATCH(LARGE(B17:D17,2),B17:D17,0)) -> A

Sheet Sensitivity_C1
A1: One-way Sensitivity: Weight on C1: EMV (T=5)
A2: Sweep w(C1) from 0→1. Other 5 weights = (1-w)/5 each. Closed-form thresholds at bottom.
A4: w(C1) | B4: Other(each) | C4: Option A | D4: Option B | E4: Option C | F4: Leader
A5: 0 | B5: =(1-A5)/5 -> 0.2 | C5: =A5*Scores!D6+B5*(SUM(Scores!D6:D11)-Scores!D6) -> 78 | D5: =A5*Scores!E6+B5*(SUM(Scores!E6:E11)-Scores!E6) -> 21 | E5: =A5*Scores!F6+B5*(SUM(Scores!F6:F11)-Scores!F6) -> 64.8 | F5: =INDEX({"A","B","C"},MATCH(MAX(C5:E5),C5:E5,0)) -> A
A6: 0.02 | B6: =(1-A6)/5 -> 0.196 | C6: =A6*Scores!D6+B6*(SUM(Scores!D6:D11)-Scores!D6) -> 76.44 | D6: =A6*Scores!E6+B6*(SUM(Scores!E6:E11)-Scores!E6) -> 22.58 | E6: =A6*Scores!F6+B6*(SUM(Scores!F6:F11)-Scores!F6) -> 64.444 | F6: =INDEX({"A","B","C"},MATCH(MAX(C6:E6),C6:E6,0)) -> A
A7: 0.04 | B7: =(1-A7)/5 -> 0.192 | C7: =A7*Scores!D6+B7*(SUM(Scores!D6:D11)-Scores!D6) -> 74.88 | D7: =A7*Scores!E6+B7*(SUM(Scores!E6:E11)-Scores!E6) -> 24.16 | E7: =A7*Scores!F6+B7*(SUM(Scores!F6:F11)-Scores!F6) -> 64.088 | F7: =INDEX({"A","B","C"},MATCH(MAX(C7:E7),C7:E7,0)) -> A
A8: 0.06 | B8: =(1-A8)/5 -> 0.188 | C8: =A8*Scores!D6+B8*(SUM(Scores!D6:D11)-Scores!D6) -> 73.32 | D8: =A8*Scores!E6+B8*(SUM(Scores!E6:E11)-Scores!E6) -> 25.74 | E8: =A8*Scores!F6+B8*(SUM(Scores!F6:F11)-Scores!F6) -> 63.732 | F8: =INDEX({"A","B","C"},MATCH(MAX(C8:E8),C8:E8,0)) -> A
A9: 0.08 | B9: =(1-A9)/5 -> 0.184 | C9: =A9*Scores!D6+B9*(SUM(Scores!D6:D11)-Scores!D6) -> 71.76 | D9: =A9*Scores!E6+B9*(SUM(Scores!E6:E11)-Scores!E6) -> 27.32 | E9: =A9*Scores!F6+B9*(SUM(Scores!F6:F11)-Scores!F6) -> 63.376 | F9: =INDEX({"A","B","C"},MATCH(MAX(C9:E9),C9:E9,0)) -> A
A10: 0.1 | B10: =(1-A10)/5 -> 0.18 | C10: =A10*Scores!D6+B10*(SUM(Scores!D6:D11)-Scores!D6) -> 70.2 | D10: =A10*Scores!E6+B10*(SUM(Scores!E6:E11)-Scores!E6) -> 28.9 | E10: =A10*Scores!F6+B10*(SUM(Scores!F6:F11)-Scores!F6) -> 63.02 | F10: =INDEX({"A","B","C"},MATCH(MAX(C10:E10),C10:E10,0)) -> A
A11: 0.12 | B11: =(1-A11)/5 -> 0.176 | C11: =A11*Scores!D6+B11*(SUM(Scores!D6:D11)-Scores!D6) -> 68.64 | D11: =A11*Scores!E6+B11*(SUM(Scores!E6:E11)-Scores!E6) -> 30.48 | E11: =A11*Scores!F6+B11*(SUM(Scores!F6:F11)-Scores!F6) -> 62.664 | F11: =INDEX({"A","B","C"},MATCH(MAX(C11:E11),C11:E11,0)) -> A
A12: 0.14 | B12: =(1-A12)/5 -> 0.172 | C12: =A12*Scores!D6+B12*(SUM(Scores!D6:D11)-Scores!D6) -> 67.08 | D12: =A12*Scores!E6+B12*(SUM(Scores!E6:E11)-Scores!E6) -> 32.06 | E12: =A12*Scores!F6+B12*(SUM(Scores!F6:F11)-Scores!F6) -> 62.308 | F12: =INDEX({"A","B","C"},MATCH(MAX(C12:E12),C12:E12,0)) -> A
A13: 0.16 | B13: =(1-A13)/5 -> 0.168 | C13: =A13*Scores!D6+B13*(SUM(Scores!D6:D11)-Scores!D6) -> 65.52 | D13: =A13*Scores!E6+B13*(SUM(Scores!E6:E11)-Scores!E6) -> 33.64 | E13: =A13*Scores!F6+B13*(SUM(Scores!F6:F11)-Scores!F6) -> 61.952 | F13: =INDEX({"A","B","C"},MATCH(MAX(C13:E13),C13:E13,0)) -> A
A14: 0.18 | B14: =(1-A14)/5 -> 0.164 | C14: =A14*Scores!D6+B14*(SUM(Scores!D6:D11)-Scores!D6) -> 63.96 | D14: =A14*Scores!E6+B14*(SUM(Scores!E6:E11)-Scores!E6) -> 35.22 | E14: =A14*Scores!F6+B14*(SUM(Scores!F6:F11)-Scores!F6) -> 61.596 | F14: =INDEX({"A","B","C"},MATCH(MAX(C14:E14),C14:E14,0)) -> A
A15: 0.2 | B15: =(1-A15)/5 -> 0.16 | C15: =A15*Scores!D6+B15*(SUM(Scores!D6:D11)-Scores!D6) -> 62.4 | D15: =A15*Scores!E6+B15*(SUM(Scores!E6:E11)-Scores!E6) -> 36.8 | E15: =A15*Scores!F6+B15*(SUM(Scores!F6:F11)-Scores!F6) -> 61.24 | F15: =INDEX({"A","B","C"},MATCH(MAX(C15:E15),C15:E15,0)) -> A
A16: 0.22 | B16: =(1-A16)/5 -> 0.156 | C16: =A16*Scores!D6+B16*(SUM(Scores!D6:D11)-Scores!D6) -> 60.84 | D16: =A16*Scores!E6+B16*(SUM(Scores!E6:E11)-Scores!E6) -> 38.38 | E16: =A16*Scores!F6+B16*(SUM(Scores!F6:F11)-Scores!F6) -> 60.884 | F16: =INDEX({"A","B","C"},MATCH(MAX(C16:E16),C16:E16,0)) -> C
A17: 0.24 | B17: =(1-A17)/5 -> 0.152 | C17: =A17*Scores!D6+B17*(SUM(Scores!D6:D11)-Scores!D6) -> 59.28 | D17: =A17*Scores!E6+B17*(SUM(Scores!E6:E11)-Scores!E6) -> 39.96 | E17: =A17*Scores!F6+B17*(SUM(Scores!F6:F11)-Scores!F6) -> 60.528 | F17: =INDEX({"A","B","C"},MATCH(MAX(C17:E17),C17:E17,0)) -> C
A18: 0.26 | B18: =(1-A18)/5 -> 0.148 | C18: =A18*Scores!D6+B18*(SUM(Scores!D6:D11)-Scores!D6) -> 57.72 | D18: =A18*Scores!E6+B18*(SUM(Scores!E6:E11)-Scores!E6) -> 41.54 | E18: =A18*Scores!F6+B18*(SUM(Scores!F6:F11)-Scores!F6) -> 60.172 | F18: =INDEX({"A","B","C"},MATCH(MAX(C18:E18),C18:E18,0)) -> C
A19: 0.28 | B19: =(1-A19)/5 -> 0.144 | C19: =A19*Scores!D6+B19*(SUM(Scores!D6:D11)-Scores!D6) -> 56.16 | D19: =A19*Scores!E6+B19*(SUM(Scores!E6:E11)-Scores!E6) -> 43.12 | E19: =A19*Scores!F6+B19*(SUM(Scores!F6:F11)-Scores!F6) -> 59.816 | F19: =INDEX({"A","B","C"},MATCH(MAX(C19:E19),C19:E19,0)) -> C
A20: 0.3 | B20: =(1-A20)/5 -> 0.14 | C20: =A20*Scores!D6+B20*(SUM(Scores!D6:D11)-Scores!D6) -> 54.6 | D20: =A20*Scores!E6+B20*(SUM(Scores!E6:E11)-Scores!E6) -> 44.7 | E20: =A20*Scores!F6+B20*(SUM(Scores!F6:F11)-Scores!F6) -> 59.46 | F20: =INDEX({"A","B","C"},MATCH(MAX(C20:E20),C20:E20,0)) -> C
A21: 0.32 | B21: =(1-A21)/5 -> 0.136 | C21: =A21*Scores!D6+B21*(SUM(Scores!D6:D11)-Scores!D6) -> 53.04 | D21: =A21*Scores!E6+B21*(SUM(Scores!E6:E11)-Scores!E6) -> 46.28 | E21: =A21*Scores!F6+B21*(SUM(Scores!F6:F11)-Scores!F6) -> 59.104 | F21: =INDEX({"A","B","C"},MATCH(MAX(C21:E21),C21:E21,0)) -> C
A22: 0.34 | B22: =(1-A22)/5 -> 0.132 | C22: =A22*Scores!D6+B22*(SUM(Scores!D6:D11)-Scores!D6) -> 51.48 | D22: =A22*Scores!E6+B22*(SUM(Scores!E6:E11)-Scores!E6) -> 47.86 | E22: =A22*Scores!F6+B22*(SUM(Scores!F6:F11)-Scores!F6) -> 58.748 | F22: =INDEX({"A","B","C"},MATCH(MAX(C22:E22),C22:E22,0)) -> C
A23: 0.36 | B23: =(1-A23)/5 -> 0.128 | C23: =A23*Scores!D6+B23*(SUM(Scores!D6:D11)-Scores!D6) -> 49.92 | D23: =A23*Scores!E6+B23*(SUM(Scores!E6:E11)-Scores!E6) -> 49.44 | E23: =A23*Scores!F6+B23*(SUM(Scores!F6:F11)-Scores!F6) -> 58.392 | F23: =INDEX({"A","B","C"},MATCH(MAX(C23:E23),C23:E23,0)) -> C
A24: 0.38 | B24: =(1-A24)/5 -> 0.124 | C24: =A24*Scores!D6+B24*(SUM(Scores!D6:D11)-Scores!D6) -> 48.36 | D24: =A24*Scores!E6+B24*(SUM(Scores!E6:E11)-Scores!E6) -> 51.02 | E24: =A24*Scores!F6+B24*(SUM(Scores!F6:F11)-Scores!F6) -> 58.036 | F24: =INDEX({"A","B","C"},MATCH(MAX(C24:E24),C24:E24,0)) -> C
A25: 0.4 | B25: =(1-A25)/5 -> 0.12 | C25: =A25*Scores!D6+B25*(SUM(Scores!D6:D11)-Scores!D6) -> 46.8 | D25: =A25*Scores!E6+B25*(SUM(Scores!E6:E11)-Scores!E6) -> 52.6 | E25: =A25*Scores!F6+B25*(SUM(Scores!F6:F11)-Scores!F6) -> 57.68 | F25: =INDEX({"A","B","C"},MATCH(MAX(C25:E25),C25:E25,0)) -> C
A26: 0.42 | B26: =(1-A26)/5 -> 0.116 | C26: =A26*Scores!D6+B26*(SUM(Scores!D6:D11)-Scores!D6) -> 45.24 | D26: =A26*Scores!E6+B26*(SUM(Scores!E6:E11)-Scores!E6) -> 54.18 | E26: =A26*Scores!F6+B26*(SUM(Scores!F6:F11)-Scores!F6) -> 57.324 | F26: =INDEX({"A","B","C"},MATCH(MAX(C26:E26),C26:E26,0)) -> C
A27: 0.44 | B27: =(1-A27)/5 -> 0.112 | C27: =A27*Scores!D6+B27*(SUM(Scores!D6:D11)-Scores!D6) -> 43.68 | D27: =A27*Scores!E6+B27*(SUM(Scores!E6:E11)-Scores!E6) -> 55.76 | E27: =A27*Scores!F6+B27*(SUM(Scores!F6:F11)-Scores!F6) -> 56.968 | F27: =INDEX({"A","B","C"},MATCH(MAX(C27:E27),C27:E27,0)) -> C
A28: 0.46 | B28: =(1-A28)/5 -> 0.108 | C28: =A28*Scores!D6+B28*(SUM(Scores!D6:D11)-Scores!D6) -> 42.12 | D28: =A28*Scores!E6+B28*(SUM(Scores!E6:E11)-Scores!E6) -> 57.34 | E28: =A28*Scores!F6+B28*(SUM(Scores!F6:F11)-Scores!F6) -> 56.612 | F28: =INDEX({"A","B","C"},MATCH(MAX(C28:E28),C28:E28,0)) -> B
A29: 0.48 | B29: =(1-A29)/5 -> 0.104 | C29: =A29*Scores!D6+B29*(SUM(Scores!D6:D11)-Scores!D6) -> 40.56 | D29: =A29*Scores!E6+B29*(SUM(Scores!E6:E11)-Scores!E6) -> 58.92 | E29: =A29*Scores!F6+B29*(SUM(Scores!F6:F11)-Scores!F6) -> 56.256 | F29: =INDEX({"A","B","C"},MATCH(MAX(C29:E29),C29:E29,0)) -> B
A30: 0.5 | B30: =(1-A30)/5 -> 0.1 | C30: =A30*Scores!D6+B30*(SUM(Scores!D6:D11)-Scores!D6) -> 39 | D30: =A30*Scores!E6+B30*(SUM(Scores!E6:E11)-Scores!E6) -> 60.5 | E30: =A30*Scores!F6+B30*(SUM(Scores!F6:F11)-Scores!F6) -> 55.9 | F30: =INDEX({"A","B","C"},MATCH(MAX(C30:E30),C30:E30,0)) -> B
A31: 0.52 | B31: =(1-A31)/5 -> 0.096 | C31: =A31*Scores!D6+B31*(SUM(Scores!D6:D11)-Scores!D6) -> 37.44 | D31: =A31*Scores!E6+B31*(SUM(Scores!E6:E11)-Scores!E6) -> 62.08 | E31: =A31*Scores!F6+B31*(SUM(Scores!F6:F11)-Scores!F6) -> 55.544 | F31: =INDEX({"A","B","C"},MATCH(MAX(C31:E31),C31:E31,0)) -> B
A32: 0.54 | B32: =(1-A32)/5 -> 0.092 | C32: =A32*Scores!D6+B32*(SUM(Scores!D6:D11)-Scores!D6) -> 35.88 | D32: =A32*Scores!E6+B32*(SUM(Scores!E6:E11)-Scores!E6) -> 63.66 | E32: =A32*Scores!F6+B32*(SUM(Scores!F6:F11)-Scores!F6) -> 55.188 | F32: =INDEX({"A","B","C"},MATCH(MAX(C32:E32),C32:E32,0)) -> B
A33: 0.56 | B33: =(1-A33)/5 -> 0.088 | C33: =A33*Scores!D6+B33*(SUM(Scores!D6:D11)-Scores!D6) -> 34.32 | D33: =A33*Scores!E6+B33*(SUM(Scores!E6:E11)-Scores!E6) -> 65.24 | E33: =A33*Scores!F6+B33*(SUM(Scores!F6:F11)-Scores!F6) -> 54.832 | F33: =INDEX({"A","B","C"},MATCH(MAX(C33:E33),C33:E33,0)) -> B
A34: 0.58 | B34: =(1-A34)/5 -> 0.084 | C34: =A34*Scores!D6+B34*(SUM(Scores!D6:D11)-Scores!D6) -> 32.76 | D34: =A34*Scores!E6+B34*(SUM(Scores!E6:E11)-Scores!E6) -> 66.82 | E34: =A34*Scores!F6+B34*(SUM(Scores!F6:F11)-Scores!F6) -> 54.476 | F34: =INDEX({"A","B","C"},MATCH(MAX(C34:E34),C34:E34,0)) -> B
A35: 0.6 | B35: =(1-A35)/5 -> 0.08 | C35: =A35*Scores!D6+B35*(SUM(Scores!D6:D11)-Scores!D6) -> 31.2 | D35: =A35*Scores!E6+B35*(SUM(Scores!E6:E11)-Scores!E6) -> 68.4 | E35: =A35*Scores!F6+B35*(SUM(Scores!F6:F11)-Scores!F6) -> 54.12 | F35: =INDEX({"A","B","C"},MATCH(MAX(C35:E35),C35:E35,0)) -> B
A36: 0.62 | B36: =(1-A36)/5 -> 0.076 | C36: =A36*Scores!D6+B36*(SUM(Scores!D6:D11)-Scores!D6) -> 29.64 | D36: =A36*Scores!E6+B36*(SUM(Scores!E6:E11)-Scores!E6) -> 69.98 | E36: =A36*Scores!F6+B36*(SUM(Scores!F6:F11)-Scores!F6) -> 53.764 | F36: =INDEX({"A","B","C"},MATCH(MAX(C36:E36),C36:E36,0)) -> B
A37: 0.64 | B37: =(1-A37)/5 -> 0.072 | C37: =A37*Scores!D6+B37*(SUM(Scores!D6:D11)-Scores!D6) -> 28.08 | D37: =A37*Scores!E6+B37*(SUM(Scores!E6:E11)-Scores!E6) -> 71.56 | E37: =A37*Scores!F6+B37*(SUM(Scores!F6:F11)-Scores!F6) -> 53.408 | F37: =INDEX({"A","B","C"},MATCH(MAX(C37:E37),C37:E37,0)) -> B
A38: 0.66 | B38: =(1-A38)/5 -> 0.068 | C38: =A38*Scores!D6+B38*(SUM(Scores!D6:D11)-Scores!D6) -> 26.52 | D38: =A38*Scores!E6+B38*(SUM(Scores!E6:E11)-Scores!E6) -> 73.14 | E38: =A38*Scores!F6+B38*(SUM(Scores!F6:F11)-Scores!F6) -> 53.052 | F38: =INDEX({"A","B","C"},MATCH(MAX(C38:E38),C38:E38,0)) -> B
A39: 0.68 | B39: =(1-A39)/5 -> 0.064 | C39: =A39*Scores!D6+B39*(SUM(Scores!D6:D11)-Scores!D6) -> 24.96 | D39: =A39*Scores!E6+B39*(SUM(Scores!E6:E11)-Scores!E6) -> 74.72 | E39: =A39*Scores!F6+B39*(SUM(Scores!F6:F11)-Scores!F6) -> 52.696 | F39: =INDEX({"A","B","C"},MATCH(MAX(C39:E39),C39:E39,0)) -> B
A40: 0.7 | B40: =(1-A40)/5 -> 0.06 | C40: =A40*Scores!D6+B40*(SUM(Scores!D6:D11)-Scores!D6) -> 23.4 | D40: =A40*Scores!E6+B40*(SUM(Scores!E6:E11)-Scores!E6) -> 76.3 | E40: =A40*Scores!F6+B40*(SUM(Scores!F6:F11)-Scores!F6) -> 52.34 | F40: =INDEX({"A","B","C"},MATCH(MAX(C40:E40),C40:E40,0)) -> B
A41: 0.72 | B41: =(1-A41)/5 -> 0.056 | C41: =A41*Scores!D6+B41*(SUM(Scores!D6:D11)-Scores!D6) -> 21.84 | D41: =A41*Scores!E6+B41*(SUM(Scores!E6:E11)-Scores!E6) -> 77.88 | E41: =A41*Scores!F6+B41*(SUM(Scores!F6:F11)-Scores!F6) -> 51.984 | F41: =INDEX({"A","B","C"},MATCH(MAX(C41:E41),C41:E41,0)) -> B
...

Sheet Sensitivity_C2
A1: One-way Sensitivity: Weight on C2: Downside (T=5)
A2: Sweep w(C2) from 0→1. Other 5 weights = (1-w)/5 each. Closed-form thresholds at bottom.
A4: w(C2) | B4: Other(each) | C4: Option A | D4: Option B | E4: Option C | F4: Leader
A5: 0 | B5: =(1-A5)/5 -> 0.2 | C5: =A5*Scores!D7+B5*(SUM(Scores!D6:D11)-Scores!D7) -> 58 | D5: =A5*Scores!E7+B5*(SUM(Scores!E6:E11)-Scores!E7) -> 41 | E5: =A5*Scores!F7+B5*(SUM(Scores!F6:F11)-Scores!F7) -> 62.4 | F5: =INDEX({"A","B","C"},MATCH(MAX(C5:E5),C5:E5,0)) -> C
A6: 0.02 | B6: =(1-A6)/5 -> 0.196 | C6: =A6*Scores!D7+B6*(SUM(Scores!D6:D11)-Scores!D7) -> 58.84 | D6: =A6*Scores!E7+B6*(SUM(Scores!E6:E11)-Scores!E7) -> 40.18 | E6: =A6*Scores!F7+B6*(SUM(Scores!F6:F11)-Scores!F7) -> 62.332 | F6: =INDEX({"A","B","C"},MATCH(MAX(C6:E6),C6:E6,0)) -> C
A7: 0.04 | B7: =(1-A7)/5 -> 0.192 | C7: =A7*Scores!D7+B7*(SUM(Scores!D6:D11)-Scores!D7) -> 59.68 | D7: =A7*Scores!E7+B7*(SUM(Scores!E6:E11)-Scores!E7) -> 39.36 | E7: =A7*Scores!F7+B7*(SUM(Scores!F6:F11)-Scores!F7) -> 62.264 | F7: =INDEX({"A","B","C"},MATCH(MAX(C7:E7),C7:E7,0)) -> C
A8: 0.06 | B8: =(1-A8)/5 -> 0.188 | C8: =A8*Scores!D7+B8*(SUM(Scores!D6:D11)-Scores!D7) -> 60.52 | D8: =A8*Scores!E7+B8*(SUM(Scores!E6:E11)-Scores!E7) -> 38.54 | E8: =A8*Scores!F7+B8*(SUM(Scores!F6:F11)-Scores!F7) -> 62.196 | F8: =INDEX({"A","B","C"},MATCH(MAX(C8:E8),C8:E8,0)) -> C
A9: 0.08 | B9: =(1-A9)/5 -> 0.184 | C9: =A9*Scores!D7+B9*(SUM(Scores!D6:D11)-Scores!D7) -> 61.36 | D9: =A9*Scores!E7+B9*(SUM(Scores!E6:E11)-Scores!E7) -> 37.72 | E9: =A9*Scores!F7+B9*(SUM(Scores!F6:F11)-Scores!F7) -> 62.128 | F9: =INDEX({"A","B","C"},MATCH(MAX(C9:E9),C9:E9,0)) -> C
A10: 0.1 | B10: =(1-A10)/5 -> 0.18 | C10: =A10*Scores!D7+B10*(SUM(Scores!D6:D11)-Scores!D7) -> 62.2 | D10: =A10*Scores!E7+B10*(SUM(Scores!E6:E11)-Scores!E7) -> 36.9 | E10: =A10*Scores!F7+B10*(SUM(Scores!F6:F11)-Scores!F7) -> 62.06 | F10: =INDEX({"A","B","C"},MATCH(MAX(C10:E10),C10:E10,0)) -> A
A11: 0.12 | B11: =(1-A11)/5 -> 0.176 | C11: =A11*Scores!D7+B11*(SUM(Scores!D6:D11)-Scores!D7) -> 63.04 | D11: =A11*Scores!E7+B11*(SUM(Scores!E6:E11)-Scores!E7) -> 36.08 | E11: =A11*Scores!F7+B11*(SUM(Scores!F6:F11)-Scores!F7) -> 61.992 | F11: =INDEX({"A","B","C"},MATCH(MAX(C11:E11),C11:E11,0)) -> A
A12: 0.14 | B12: =(1-A12)/5 -> 0.172 | C12: =A12*Scores!D7+B12*(SUM(Scores!D6:D11)-Scores!D7) -> 63.88 | D12: =A12*Scores!E7+B12*(SUM(Scores!E6:E11)-Scores!E7) -> 35.26 | E12: =A12*Scores!F7+B12*(SUM(Scores!F6:F11)-Scores!F7) -> 61.924 | F12: =INDEX({"A","B","C"},MATCH(MAX(C12:E12),C12:E12,0)) -> A
A13: 0.16 | B13: =(1-A13)/5 -> 0.168 | C13: =A13*Scores!D7+B13*(SUM(Scores!D6:D11)-Scores!D7) -> 64.72 | D13: =A13*Scores!E7+B13*(SUM(Scores!E6:E11)-Scores!E7) -> 34.44 | E13: =A13*Scores!F7+B13*(SUM(Scores!F6:F11)-Scores!F7) -> 61.856 | F13: =INDEX({"A","B","C"},MATCH(MAX(C13:E13),C13:E13,0)) -> A
A14: 0.18 | B14: =(1-A14)/5 -> 0.164 | C14: =A14*Scores!D7+B14*(SUM(Scores!D6:D11)-Scores!D7) -> 65.56 | D14: =A14*Scores!E7+B14*(SUM(Scores!E6:E11)-Scores!E7) -> 33.62 | E14: =A14*Scores!F7+B14*(SUM(Scores!F6:F11)-Scores!F7) -> 61.788 | F14: =INDEX({"A","B","C"},MATCH(MAX(C14:E14),C14:E14,0)) -> A
A15: 0.2 | B15: =(1-A15)/5 -> 0.16 | C15: =A15*Scores!D7+B15*(SUM(Scores!D6:D11)-Scores!D7) -> 66.4 | D15: =A15*Scores!E7+B15*(SUM(Scores!E6:E11)-Scores!E7) -> 32.8 | E15: =A15*Scores!F7+B15*(SUM(Scores!F6:F11)-Scores!F7) -> 61.72 | F15: =INDEX({"A","B","C"},MATCH(MAX(C15:E15),C15:E15,0)) -> A
A16: 0.22 | B16: =(1-A16)/5 -> 0.156 | C16: =A16*Scores!D7+B16*(SUM(Scores!D6:D11)-Scores!D7) -> 67.24 | D16: =A16*Scores!E7+B16*(SUM(Scores!E6:E11)-Scores!E7) -> 31.98 | E16: =A16*Scores!F7+B16*(SUM(Scores!F6:F11)-Scores!F7) -> 61.652 | F16: =INDEX({"A","B","C"},MATCH(MAX(C16:E16),C16:E16,0)) -> A
A17: 0.24 | B17: =(1-A17)/5 -> 0.152 | C17: =A17*Scores!D7+B17*(SUM(Scores!D6:D11)-Scores!D7) -> 68.08 | D17: =A17*Scores!E7+B17*(SUM(Scores!E6:E11)-Scores!E7) -> 31.16 | E17: =A17*Scores!F7+B17*(SUM(Scores!F6:F11)-Scores!F7) -> 61.584 | F17: =INDEX({"A","B","C"},MATCH(MAX(C17:E17),C17:E17,0)) -> A
A18: 0.26 | B18: =(1-A18)/5 -> 0.148 | C18: =A18*Scores!D7+B18*(SUM(Scores!D6:D11)-Scores!D7) -> 68.92 | D18: =A18*Scores!E7+B18*(SUM(Scores!E6:E11)-Scores!E7) -> 30.34 | E18: =A18*Scores!F7+B18*(SUM(Scores!F6:F11)-Scores!F7) -> 61.516 | F18: =INDEX({"A","B","C"},MATCH(MAX(C18:E18),C18:E18,0)) -> A
A19: 0.28 | B19: =(1-A19)/5 -> 0.144 | C19: =A19*Scores!D7+B19*(SUM(Scores!D6:D11)-Scores!D7) -> 69.76 | D19: =A19*Scores!E7+B19*(SUM(Scores!E6:E11)-Scores!E7) -> 29.52 | E19: =A19*Scores!F7+B19*(SUM(Scores!F6:F11)-Scores!F7) -> 61.448 | F19: =INDEX({"A","B","C"},MATCH(MAX(C19:E19),C19:E19,0)) -> A
A20: 0.3 | B20: =(1-A20)/5 -> 0.14 | C20: =A20*Scores!D7+B20*(SUM(Scores!D6:D11)-Scores!D7) -> 70.6 | D20: =A20*Scores!E7+B20*(SUM(Scores!E6:E11)-Scores!E7) -> 28.7 | E20: =A20*Scores!F7+B20*(SUM(Scores!F6:F11)-Scores!F7) -> 61.38 | F20: =INDEX({"A","B","C"},MATCH(MAX(C20:E20),C20:E20,0)) -> A
A21: 0.32 | B21: =(1-A21)/5 -> 0.136 | C21: =A21*Scores!D7+B21*(SUM(Scores!D6:D11)-Scores!D7) -> 71.44 | D21: =A21*Scores!E7+B21*(SUM(Scores!E6:E11)-Scores!E7) -> 27.88 | E21: =A21*Scores!F7+B21*(SUM(Scores!F6:F11)-Scores!F7) -> 61.312 | F21: =INDEX({"A","B","C"},MATCH(MAX(C21:E21),C21:E21,0)) -> A
A22: 0.34 | B22: =(1-A22)/5 -> 0.132 | C22: =A22*Scores!D7+B22*(SUM(Scores!D6:D11)-Scores!D7) -> 72.28 | D22: =A22*Scores!E7+B22*(SUM(Scores!E6:E11)-Scores!E7) -> 27.06 | E22: =A22*Scores!F7+B22*(SUM(Scores!F6:F11)-Scores!F7) -> 61.244 | F22: =INDEX({"A","B","C"},MATCH(MAX(C22:E22),C22:E22,0)) -> A
A23: 0.36 | B23: =(1-A23)/5 -> 0.128 | C23: =A23*Scores!D7+B23*(SUM(Scores!D6:D11)-Scores!D7) -> 73.12 | D23: =A23*Scores!E7+B23*(SUM(Scores!E6:E11)-Scores!E7) -> 26.24 | E23: =A23*Scores!F7+B23*(SUM(Scores!F6:F11)-Scores!F7) -> 61.176 | F23: =INDEX({"A","B","C"},MATCH(MAX(C23:E23),C23:E23,0)) -> A
A24: 0.38 | B24: =(1-A24)/5 -> 0.124 | C24: =A24*Scores!D7+B24*(SUM(Scores!D6:D11)-Scores!D7) -> 73.96 | D24: =A24*Scores!E7+B24*(SUM(Scores!E6:E11)-Scores!E7) -> 25.42 | E24: =A24*Scores!F7+B24*(SUM(Scores!F6:F11)-Scores!F7) -> 61.108 | F24: =INDEX({"A","B","C"},MATCH(MAX(C24:E24),C24:E24,0)) -> A
A25: 0.4 | B25: =(1-A25)/5 -> 0.12 | C25: =A25*Scores!D7+B25*(SUM(Scores!D6:D11)-Scores!D7) -> 74.8 | D25: =A25*Scores!E7+B25*(SUM(Scores!E6:E11)-Scores!E7) -> 24.6 | E25: =A25*Scores!F7+B25*(SUM(Scores!F6:F11)-Scores!F7) -> 61.04 | F25: =INDEX({"A","B","C"},MATCH(MAX(C25:E25),C25:E25,0)) -> A
A26: 0.42 | B26: =(1-A26)/5 -> 0.116 | C26: =A26*Scores!D7+B26*(SUM(Scores!D6:D11)-Scores!D7) -> 75.64 | D26: =A26*Scores!E7+B26*(SUM(Scores!E6:E11)-Scores!E7) -> 23.78 | E26: =A26*Scores!F7+B26*(SUM(Scores!F6:F11)-Scores!F7) -> 60.972 | F26: =INDEX({"A","B","C"},MATCH(MAX(C26:E26),C26:E26,0)) -> A
A27: 0.44 | B27: =(1-A27)/5 -> 0.112 | C27: =A27*Scores!D7+B27*(SUM(Scores!D6:D11)-Scores!D7) -> 76.48 | D27: =A27*Scores!E7+B27*(SUM(Scores!E6:E11)-Scores!E7) -> 22.96 | E27: =A27*Scores!F7+B27*(SUM(Scores!F6:F11)-Scores!F7) -> 60.904 | F27: =INDEX({"A","B","C"},MATCH(MAX(C27:E27),C27:E27,0)) -> A
A28: 0.46 | B28: =(1-A28)/5 -> 0.108 | C28: =A28*Scores!D7+B28*(SUM(Scores!D6:D11)-Scores!D7) -> 77.32 | D28: =A28*Scores!E7+B28*(SUM(Scores!E6:E11)-Scores!E7) -> 22.14 | E28: =A28*Scores!F7+B28*(SUM(Scores!F6:F11)-Scores!F7) -> 60.836 | F28: =INDEX({"A","B","C"},MATCH(MAX(C28:E28),C28:E28,0)) -> A
A29: 0.48 | B29: =(1-A29)/5 -> 0.104 | C29: =A29*Scores!D7+B29*(SUM(Scores!D6:D11)-Scores!D7) -> 78.16 | D29: =A29*Scores!E7+B29*(SUM(Scores!E6:E11)-Scores!E7) -> 21.32 | E29: =A29*Scores!F7+B29*(SUM(Scores!F6:F11)-Scores!F7) -> 60.768 | F29: =INDEX({"A","B","C"},MATCH(MAX(C29:E29),C29:E29,0)) -> A
A30: 0.5 | B30: =(1-A30)/5 -> 0.1 | C30: =A30*Scores!D7+B30*(SUM(Scores!D6:D11)-Scores!D7) -> 79 | D30: =A30*Scores!E7+B30*(SUM(Scores!E6:E11)-Scores!E7) -> 20.5 | E30: =A30*Scores!F7+B30*(SUM(Scores!F6:F11)-Scores!F7) -> 60.7 | F30: =INDEX({"A","B","C"},MATCH(MAX(C30:E30),C30:E30,0)) -> A
A31: 0.52 | B31: =(1-A31)/5 -> 0.096 | C31: =A31*Scores!D7+B31*(SUM(Scores!D6:D11)-Scores!D7) -> 79.84 | D31: =A31*Scores!E7+B31*(SUM(Scores!E6:E11)-Scores!E7) -> 19.68 | E31: =A31*Scores!F7+B31*(SUM(Scores!F6:F11)-Scores!F7) -> 60.632 | F31: =INDEX({"A","B","C"},MATCH(MAX(C31:E31),C31:E31,0)) -> A
A32: 0.54 | B32: =(1-A32)/5 -> 0.092 | C32: =A32*Scores!D7+B32*(SUM(Scores!D6:D11)-Scores!D7) -> 80.68 | D32: =A32*Scores!E7+B32*(SUM(Scores!E6:E11)-Scores!E7) -> 18.86 | E32: =A32*Scores!F7+B32*(SUM(Scores!F6:F11)-Scores!F7) -> 60.564 | F32: =INDEX({"A","B","C"},MATCH(MAX(C32:E32),C32:E32,0)) -> A
A33: 0.56 | B33: =(1-A33)/5 -> 0.088 | C33: =A33*Scores!D7+B33*(SUM(Scores!D6:D11)-Scores!D7) -> 81.52 | D33: =A33*Scores!E7+B33*(SUM(Scores!E6:E11)-Scores!E7) -> 18.04 | E33: =A33*Scores!F7+B33*(SUM(Scores!F6:F11)-Scores!F7) -> 60.496 | F33: =INDEX({"A","B","C"},MATCH(MAX(C33:E33),C33:E33,0)) -> A
A34: 0.58 | B34: =(1-A34)/5 -> 0.084 | C34: =A34*Scores!D7+B34*(SUM(Scores!D6:D11)-Scores!D7) -> 82.36 | D34: =A34*Scores!E7+B34*(SUM(Scores!E6:E11)-Scores!E7) -> 17.22 | E34: =A34*Scores!F7+B34*(SUM(Scores!F6:F11)-Scores!F7) -> 60.428 | F34: =INDEX({"A","B","C"},MATCH(MAX(C34:E34),C34:E34,0)) -> A
A35: 0.6 | B35: =(1-A35)/5 -> 0.08 | C35: =A35*Scores!D7+B35*(SUM(Scores!D6:D11)-Scores!D7) -> 83.2 | D35: =A35*Scores!E7+B35*(SUM(Scores!E6:E11)-Scores!E7) -> 16.4 | E35: =A35*Scores!F7+B35*(SUM(Scores!F6:F11)-Scores!F7) -> 60.36 | F35: =INDEX({"A","B","C"},MATCH(MAX(C35:E35),C35:E35,0)) -> A
A36: 0.62 | B36: =(1-A36)/5 -> 0.076 | C36: =A36*Scores!D7+B36*(SUM(Scores!D6:D11)-Scores!D7) -> 84.04 | D36: =A36*Scores!E7+B36*(SUM(Scores!E6:E11)-Scores!E7) -> 15.58 | E36: =A36*Scores!F7+B36*(SUM(Scores!F6:F11)-Scores!F7) -> 60.292 | F36: =INDEX({"A","B","C"},MATCH(MAX(C36:E36),C36:E36,0)) -> A
A37: 0.64 | B37: =(1-A37)/5 -> 0.072 | C37: =A37*Scores!D7+B37*(SUM(Scores!D6:D11)-Scores!D7) -> 84.88 | D37: =A37*Scores!E7+B37*(SUM(Scores!E6:E11)-Scores!E7) -> 14.76 | E37: =A37*Scores!F7+B37*(SUM(Scores!F6:F11)-Scores!F7) -> 60.224 | F37: =INDEX({"A","B","C"},MATCH(MAX(C37:E37),C37:E37,0)) -> A
A38: 0.66 | B38: =(1-A38)/5 -> 0.068 | C38: =A38*Scores!D7+B38*(SUM(Scores!D6:D11)-Scores!D7) -> 85.72 | D38: =A38*Scores!E7+B38*(SUM(Scores!E6:E11)-Scores!E7) -> 13.94 | E38: =A38*Scores!F7+B38*(SUM(Scores!F6:F11)-Scores!F7) -> 60.156 | F38: =INDEX({"A","B","C"},MATCH(MAX(C38:E38),C38:E38,0)) -> A
A39: 0.68 | B39: =(1-A39)/5 -> 0.064 | C39: =A39*Scores!D7+B39*(SUM(Scores!D6:D11)-Scores!D7) -> 86.56 | D39: =A39*Scores!E7+B39*(SUM(Scores!E6:E11)-Scores!E7) -> 13.12 | E39: =A39*Scores!F7+B39*(SUM(Scores!F6:F11)-Scores!F7) -> 60.088 | F39: =INDEX({"A","B","C"},MATCH(MAX(C39:E39),C39:E39,0)) -> A
A40: 0.7 | B40: =(1-A40)/5 -> 0.06 | C40: =A40*Scores!D7+B40*(SUM(Scores!D6:D11)-Scores!D7) -> 87.4 | D40: =A40*Scores!E7+B40*(SUM(Scores!E6:E11)-Scores!E7) -> 12.3 | E40: =A40*Scores!F7+B40*(SUM(Scores!F6:F11)-Scores!F7) -> 60.02 | F40: =INDEX({"A","B","C"},MATCH(MAX(C40:E40),C40:E40,0)) -> A
A41: 0.72 | B41: =(1-A41)/5 -> 0.056 | C41: =A41*Scores!D7+B41*(SUM(Scores!D6:D11)-Scores!D7) -> 88.24 | D41: =A41*Scores!E7+B41*(SUM(Scores!E6:E11)-Scores!E7) -> 11.48 | E41: =A41*Scores!F7+B41*(SUM(Scores!F6:F11)-Scores!F7) -> 59.952 | F41: =INDEX({"A","B","C"},MATCH(MAX(C41:E41),C41:E41,0)) -> A
...

Sheet Sensitivity_C3
A1: One-way Sensitivity: Weight on C3: UK licence (T=5)
A2: Sweep w(C3) from 0→1. Other 5 weights = (1-w)/5 each. Closed-form thresholds at bottom.
A4: w(C3) | B4: Other(each) | C4: Option A | D4: Option B | E4: Option C | F4: Leader
A5: 0 | B5: =(1-A5)/5 -> 0.2 | C5: =A5*Scores!D8+B5*(SUM(Scores!D6:D11)-Scores!D8) -> 61 | D5: =A5*Scores!E8+B5*(SUM(Scores!E6:E11)-Scores!E8) -> 37 | E5: =A5*Scores!F8+B5*(SUM(Scores!F6:F11)-Scores!F8) -> 65.2 | F5: =INDEX({"A","B","C"},MATCH(MAX(C5:E5),C5:E5,0)) -> C
A6: 0.02 | B6: =(1-A6)/5 -> 0.196 | C6: =A6*Scores!D8+B6*(SUM(Scores!D6:D11)-Scores!D8) -> 61.48 | D6: =A6*Scores!E8+B6*(SUM(Scores!E6:E11)-Scores!E8) -> 36.66 | E6: =A6*Scores!F8+B6*(SUM(Scores!F6:F11)-Scores!F8) -> 64.796 | F6: =INDEX({"A","B","C"},MATCH(MAX(C6:E6),C6:E6,0)) -> C
A7: 0.04 | B7: =(1-A7)/5 -> 0.192 | C7: =A7*Scores!D8+B7*(SUM(Scores!D6:D11)-Scores!D8) -> 61.96 | D7: =A7*Scores!E8+B7*(SUM(Scores!E6:E11)-Scores!E8) -> 36.32 | E7: =A7*Scores!F8+B7*(SUM(Scores!F6:F11)-Scores!F8) -> 64.392 | F7: =INDEX({"A","B","C"},MATCH(MAX(C7:E7),C7:E7,0)) -> C
A8: 0.06 | B8: =(1-A8)/5 -> 0.188 | C8: =A8*Scores!D8+B8*(SUM(Scores!D6:D11)-Scores!D8) -> 62.44 | D8: =A8*Scores!E8+B8*(SUM(Scores!E6:E11)-Scores!E8) -> 35.98 | E8: =A8*Scores!F8+B8*(SUM(Scores!F6:F11)-Scores!F8) -> 63.988 | F8: =INDEX({"A","B","C"},MATCH(MAX(C8:E8),C8:E8,0)) -> C
A9: 0.08 | B9: =(1-A9)/5 -> 0.184 | C9: =A9*Scores!D8+B9*(SUM(Scores!D6:D11)-Scores!D8) -> 62.92 | D9: =A9*Scores!E8+B9*(SUM(Scores!E6:E11)-Scores!E8) -> 35.64 | E9: =A9*Scores!F8+B9*(SUM(Scores!F6:F11)-Scores!F8) -> 63.584 | F9: =INDEX({"A","B","C"},MATCH(MAX(C9:E9),C9:E9,0)) -> C
A10: 0.1 | B10: =(1-A10)/5 -> 0.18 | C10: =A10*Scores!D8+B10*(SUM(Scores!D6:D11)-Scores!D8) -> 63.4 | D10: =A10*Scores!E8+B10*(SUM(Scores!E6:E11)-Scores!E8) -> 35.3 | E10: =A10*Scores!F8+B10*(SUM(Scores!F6:F11)-Scores!F8) -> 63.18 | F10: =INDEX({"A","B","C"},MATCH(MAX(C10:E10),C10:E10,0)) -> A
A11: 0.12 | B11: =(1-A11)/5 -> 0.176 | C11: =A11*Scores!D8+B11*(SUM(Scores!D6:D11)-Scores!D8) -> 63.88 | D11: =A11*Scores!E8+B11*(SUM(Scores!E6:E11)-Scores!E8) -> 34.96 | E11: =A11*Scores!F8+B11*(SUM(Scores!F6:F11)-Scores!F8) -> 62.776 | F11: =INDEX({"A","B","C"},MATCH(MAX(C11:E11),C11:E11,0)) -> A
A12: 0.14 | B12: =(1-A12)/5 -> 0.172 | C12: =A12*Scores!D8+B12*(SUM(Scores!D6:D11)-Scores!D8) -> 64.36 | D12: =A12*Scores!E8+B12*(SUM(Scores!E6:E11)-Scores!E8) -> 34.62 | E12: =A12*Scores!F8+B12*(SUM(Scores!F6:F11)-Scores!F8) -> 62.372 | F12: =INDEX({"A","B","C"},MATCH(MAX(C12:E12),C12:E12,0)) -> A
A13: 0.16 | B13: =(1-A13)/5 -> 0.168 | C13: =A13*Scores!D8+B13*(SUM(Scores!D6:D11)-Scores!D8) -> 64.84 | D13: =A13*Scores!E8+B13*(SUM(Scores!E6:E11)-Scores!E8) -> 34.28 | E13: =A13*Scores!F8+B13*(SUM(Scores!F6:F11)-Scores!F8) -> 61.968 | F13: =INDEX({"A","B","C"},MATCH(MAX(C13:E13),C13:E13,0)) -> A
A14: 0.18 | B14: =(1-A14)/5 -> 0.164 | C14: =A14*Scores!D8+B14*(SUM(Scores!D6:D11)-Scores!D8) -> 65.32 | D14: =A14*Scores!E8+B14*(SUM(Scores!E6:E11)-Scores!E8) -> 33.94 | E14: =A14*Scores!F8+B14*(SUM(Scores!F6:F11)-Scores!F8) -> 61.564 | F14: =INDEX({"A","B","C"},MATCH(MAX(C14:E14),C14:E14,0)) -> A
A15: 0.2 | B15: =(1-A15)/5 -> 0.16 | C15: =A15*Scores!D8+B15*(SUM(Scores!D6:D11)-Scores!D8) -> 65.8 | D15: =A15*Scores!E8+B15*(SUM(Scores!E6:E11)-Scores!E8) -> 33.6 | E15: =A15*Scores!F8+B15*(SUM(Scores!F6:F11)-Scores!F8) -> 61.16 | F15: =INDEX({"A","B","C"},MATCH(MAX(C15:E15),C15:E15,0)) -> A
A16: 0.22 | B16: =(1-A16)/5 -> 0.156 | C16: =A16*Scores!D8+B16*(SUM(Scores!D6:D11)-Scores!D8) -> 66.28 | D16: =A16*Scores!E8+B16*(SUM(Scores!E6:E11)-Scores!E8) -> 33.26 | E16: =A16*Scores!F8+B16*(SUM(Scores!F6:F11)-Scores!F8) -> 60.756 | F16: =INDEX({"A","B","C"},MATCH(MAX(C16:E16),C16:E16,0)) -> A
A17: 0.24 | B17: =(1-A17)/5 -> 0.152 | C17: =A17*Scores!D8+B17*(SUM(Scores!D6:D11)-Scores!D8) -> 66.76 | D17: =A17*Scores!E8+B17*(SUM(Scores!E6:E11)-Scores!E8) -> 32.92 | E17: =A17*Scores!F8+B17*(SUM(Scores!F6:F11)-Scores!F8) -> 60.352 | F17: =INDEX({"A","B","C"},MATCH(MAX(C17:E17),C17:E17,0)) -> A
A18: 0.26 | B18: =(1-A18)/5 -> 0.148 | C18: =A18*Scores!D8+B18*(SUM(Scores!D6:D11)-Scores!D8) -> 67.24 | D18: =A18*Scores!E8+B18*(SUM(Scores!E6:E11)-Scores!E8) -> 32.58 | E18: =A18*Scores!F8+B18*(SUM(Scores!F6:F11)-Scores!F8) -> 59.948 | F18: =INDEX({"A","B","C"},MATCH(MAX(C18:E18),C18:E18,0)) -> A
A19: 0.28 | B19: =(1-A19)/5 -> 0.144 | C19: =A19*Scores!D8+B19*(SUM(Scores!D6:D11)-Scores!D8) -> 67.72 | D19: =A19*Scores!E8+B19*(SUM(Scores!E6:E11)-Scores!E8) -> 32.24 | E19: =A19*Scores!F8+B19*(SUM(Scores!F6:F11)-Scores!F8) -> 59.544 | F19: =INDEX({"A","B","C"},MATCH(MAX(C19:E19),C19:E19,0)) -> A
A20: 0.3 | B20: =(1-A20)/5 -> 0.14 | C20: =A20*Scores!D8+B20*(SUM(Scores!D6:D11)-Scores!D8) -> 68.2 | D20: =A20*Scores!E8+B20*(SUM(Scores!E6:E11)-Scores!E8) -> 31.9 | E20: =A20*Scores!F8+B20*(SUM(Scores!F6:F11)-Scores!F8) -> 59.14 | F20: =INDEX({"A","B","C"},MATCH(MAX(C20:E20),C20:E20,0)) -> A
A21: 0.32 | B21: =(1-A21)/5 -> 0.136 | C21: =A21*Scores!D8+B21*(SUM(Scores!D6:D11)-Scores!D8) -> 68.68 | D21: =A21*Scores!E8+B21*(SUM(Scores!E6:E11)-Scores!E8) -> 31.56 | E21: =A21*Scores!F8+B21*(SUM(Scores!F6:F11)-Scores!F8) -> 58.736 | F21: =INDEX({"A","B","C"},MATCH(MAX(C21:E21),C21:E21,0)) -> A
A22: 0.34 | B22: =(1-A22)/5 -> 0.132 | C22: =A22*Scores!D8+B22*(SUM(Scores!D6:D11)-Scores!D8) -> 69.16 | D22: =A22*Scores!E8+B22*(SUM(Scores!E6:E11)-Scores!E8) -> 31.22 | E22: =A22*Scores!F8+B22*(SUM(Scores!F6:F11)-Scores!F8) -> 58.332 | F22: =INDEX({"A","B","C"},MATCH(MAX(C22:E22),C22:E22,0)) -> A
A23: 0.36 | B23: =(1-A23)/5 -> 0.128 | C23: =A23*Scores!D8+B23*(SUM(Scores!D6:D11)-Scores!D8) -> 69.64 | D23: =A23*Scores!E8+B23*(SUM(Scores!E6:E11)-Scores!E8) -> 30.88 | E23: =A23*Scores!F8+B23*(SUM(Scores!F6:F11)-Scores!F8) -> 57.928 | F23: =INDEX({"A","B","C"},MATCH(MAX(C23:E23),C23:E23,0)) -> A
A24: 0.38 | B24: =(1-A24)/5 -> 0.124 | C24: =A24*Scores!D8+B24*(SUM(Scores!D6:D11)-Scores!D8) -> 70.12 | D24: =A24*Scores!E8+B24*(SUM(Scores!E6:E11)-Scores!E8) -> 30.54 | E24: =A24*Scores!F8+B24*(SUM(Scores!F6:F11)-Scores!F8) -> 57.524 | F24: =INDEX({"A","B","C"},MATCH(MAX(C24:E24),C24:E24,0)) -> A
A25: 0.4 | B25: =(1-A25)/5 -> 0.12 | C25: =A25*Scores!D8+B25*(SUM(Scores!D6:D11)-Scores!D8) -> 70.6 | D25: =A25*Scores!E8+B25*(SUM(Scores!E6:E11)-Scores!E8) -> 30.2 | E25: =A25*Scores!F8+B25*(SUM(Scores!F6:F11)-Scores!F8) -> 57.12 | F25: =INDEX({"A","B","C"},MATCH(MAX(C25:E25),C25:E25,0)) -> A
A26: 0.42 | B26: =(1-A26)/5 -> 0.116 | C26: =A26*Scores!D8+B26*(SUM(Scores!D6:D11)-Scores!D8) -> 71.08 | D26: =A26*Scores!E8+B26*(SUM(Scores!E6:E11)-Scores!E8) -> 29.86 | E26: =A26*Scores!F8+B26*(SUM(Scores!F6:F11)-Scores!F8) -> 56.716 | F26: =INDEX({"A","B","C"},MATCH(MAX(C26:E26),C26:E26,0)) -> A
A27: 0.44 | B27: =(1-A27)/5 -> 0.112 | C27: =A27*Scores!D8+B27*(SUM(Scores!D6:D11)-Scores!D8) -> 71.56 | D27: =A27*Scores!E8+B27*(SUM(Scores!E6:E11)-Scores!E8) -> 29.52 | E27: =A27*Scores!F8+B27*(SUM(Scores!F6:F11)-Scores!F8) -> 56.312 | F27: =INDEX({"A","B","C"},MATCH(MAX(C27:E27),C27:E27,0)) -> A
A28: 0.46 | B28: =(1-A28)/5 -> 0.108 | C28: =A28*Scores!D8+B28*(SUM(Scores!D6:D11)-Scores!D8) -> 72.04 | D28: =A28*Scores!E8+B28*(SUM(Scores!E6:E11)-Scores!E8) -> 29.18 | E28: =A28*Scores!F8+B28*(SUM(Scores!F6:F11)-Scores!F8) -> 55.908 | F28: =INDEX({"A","B","C"},MATCH(MAX(C28:E28),C28:E28,0)) -> A
A29: 0.48 | B29: =(1-A29)/5 -> 0.104 | C29: =A29*Scores!D8+B29*(SUM(Scores!D6:D11)-Scores!D8) -> 72.52 | D29: =A29*Scores!E8+B29*(SUM(Scores!E6:E11)-Scores!E8) -> 28.84 | E29: =A29*Scores!F8+B29*(SUM(Scores!F6:F11)-Scores!F8) -> 55.504 | F29: =INDEX({"A","B","C"},MATCH(MAX(C29:E29),C29:E29,0)) -> A
A30: 0.5 | B30: =(1-A30)/5 -> 0.1 | C30: =A30*Scores!D8+B30*(SUM(Scores!D6:D11)-Scores!D8) -> 73 | D30: =A30*Scores!E8+B30*(SUM(Scores!E6:E11)-Scores!E8) -> 28.5 | E30: =A30*Scores!F8+B30*(SUM(Scores!F6:F11)-Scores!F8) -> 55.1 | F30: =INDEX({"A","B","C"},MATCH(MAX(C30:E30),C30:E30,0)) -> A
A31: 0.52 | B31: =(1-A31)/5 -> 0.096 | C31: =A31*Scores!D8+B31*(SUM(Scores!D6:D11)-Scores!D8) -> 73.48 | D31: =A31*Scores!E8+B31*(SUM(Scores!E6:E11)-Scores!E8) -> 28.16 | E31: =A31*Scores!F8+B31*(SUM(Scores!F6:F11)-Scores!F8) -> 54.696 | F31: =INDEX({"A","B","C"},MATCH(MAX(C31:E31),C31:E31,0)) -> A
A32: 0.54 | B32: =(1-A32)/5 -> 0.092 | C32: =A32*Scores!D8+B32*(SUM(Scores!D6:D11)-Scores!D8) -> 73.96 | D32: =A32*Scores!E8+B32*(SUM(Scores!E6:E11)-Scores!E8) -> 27.82 | E32: =A32*Scores!F8+B32*(SUM(Scores!F6:F11)-Scores!F8) -> 54.292 | F32: =INDEX({"A","B","C"},MATCH(MAX(C32:E32),C32:E32,0)) -> A
A33: 0.56 | B33: =(1-A33)/5 -> 0.088 | C33: =A33*Scores!D8+B33*(SUM(Scores!D6:D11)-Scores!D8) -> 74.44 | D33: =A33*Scores!E8+B33*(SUM(Scores!E6:E11)-Scores!E8) -> 27.48 | E33: =A33*Scores!F8+B33*(SUM(Scores!F6:F11)-Scores!F8) -> 53.888 | F33: =INDEX({"A","B","C"},MATCH(MAX(C33:E33),C33:E33,0)) -> A
A34: 0.58 | B34: =(1-A34)/5 -> 0.084 | C34: =A34*Scores!D8+B34*(SUM(Scores!D6:D11)-Scores!D8) -> 74.92 | D34: =A34*Scores!E8+B34*(SUM(Scores!E6:E11)-Scores!E8) -> 27.14 | E34: =A34*Scores!F8+B34*(SUM(Scores!F6:F11)-Scores!F8) -> 53.484 | F34: =INDEX({"A","B","C"},MATCH(MAX(C34:E34),C34:E34,0)) -> A
A35: 0.6 | B35: =(1-A35)/5 -> 0.08 | C35: =A35*Scores!D8+B35*(SUM(Scores!D6:D11)-Scores!D8) -> 75.4 | D35: =A35*Scores!E8+B35*(SUM(Scores!E6:E11)-Scores!E8) -> 26.8 | E35: =A35*Scores!F8+B35*(SUM(Scores!F6:F11)-Scores!F8) -> 53.08 | F35: =INDEX({"A","B","C"},MATCH(MAX(C35:E35),C35:E35,0)) -> A
A36: 0.62 | B36: =(1-A36)/5 -> 0.076 | C36: =A36*Scores!D8+B36*(SUM(Scores!D6:D11)-Scores!D8) -> 75.88 | D36: =A36*Scores!E8+B36*(SUM(Scores!E6:E11)-Scores!E8) -> 26.46 | E36: =A36*Scores!F8+B36*(SUM(Scores!F6:F11)-Scores!F8) -> 52.676 | F36: =INDEX({"A","B","C"},MATCH(MAX(C36:E36),C36:E36,0)) -> A
A37: 0.64 | B37: =(1-A37)/5 -> 0.072 | C37: =A37*Scores!D8+B37*(SUM(Scores!D6:D11)-Scores!D8) -> 76.36 | D37: =A37*Scores!E8+B37*(SUM(Scores!E6:E11)-Scores!E8) -> 26.12 | E37: =A37*Scores!F8+B37*(SUM(Scores!F6:F11)-Scores!F8) -> 52.272 | F37: =INDEX({"A","B","C"},MATCH(MAX(C37:E37),C37:E37,0)) -> A
A38: 0.66 | B38: =(1-A38)/5 -> 0.068 | C38: =A38*Scores!D8+B38*(SUM(Scores!D6:D11)-Scores!D8) -> 76.84 | D38: =A38*Scores!E8+B38*(SUM(Scores!E6:E11)-Scores!E8) -> 25.78 | E38: =A38*Scores!F8+B38*(SUM(Scores!F6:F11)-Scores!F8) -> 51.868 | F38: =INDEX({"A","B","C"},MATCH(MAX(C38:E38),C38:E38,0)) -> A
A39: 0.68 | B39: =(1-A39)/5 -> 0.064 | C39: =A39*Scores!D8+B39*(SUM(Scores!D6:D11)-Scores!D8) -> 77.32 | D39: =A39*Scores!E8+B39*(SUM(Scores!E6:E11)-Scores!E8) -> 25.44 | E39: =A39*Scores!F8+B39*(SUM(Scores!F6:F11)-Scores!F8) -> 51.464 | F39: =INDEX({"A","B","C"},MATCH(MAX(C39:E39),C39:E39,0)) -> A
A40: 0.7 | B40: =(1-A40)/5 -> 0.06 | C40: =A40*Scores!D8+B40*(SUM(Scores!D6:D11)-Scores!D8) -> 77.8 | D40: =A40*Scores!E8+B40*(SUM(Scores!E6:E11)-Scores!E8) -> 25.1 | E40: =A40*Scores!F8+B40*(SUM(Scores!F6:F11)-Scores!F8) -> 51.06 | F40: =INDEX({"A","B","C"},MATCH(MAX(C40:E40),C40:E40,0)) -> A
A41: 0.72 | B41: =(1-A41)/5 -> 0.056 | C41: =A41*Scores!D8+B41*(SUM(Scores!D6:D11)-Scores!D8) -> 78.28 | D41: =A41*Scores!E8+B41*(SUM(Scores!E6:E11)-Scores!E8) -> 24.76 | E41: =A41*Scores!F8+B41*(SUM(Scores!F6:F11)-Scores!F8) -> 50.656 | F41: =INDEX({"A","B","C"},MATCH(MAX(C41:E41),C41:E41,0)) -> A
...

Sheet Sensitivity_C4
A1: One-way Sensitivity: Weight on C4: Run-risk (T=5)
A2: Sweep w(C4) from 0→1. Other 5 weights = (1-w)/5 each. Closed-form thresholds at bottom.
A4: w(C4) | B4: Other(each) | C4: Option A | D4: Option B | E4: Option C | F4: Leader
A5: 0 | B5: =(1-A5)/5 -> 0.2 | C5: =A5*Scores!D9+B5*(SUM(Scores!D6:D11)-Scores!D9) -> 59 | D5: =A5*Scores!E9+B5*(SUM(Scores!E6:E11)-Scores!E9) -> 37 | E5: =A5*Scores!F9+B5*(SUM(Scores!F6:F11)-Scores!F9) -> 63.2 | F5: =INDEX({"A","B","C"},MATCH(MAX(C5:E5),C5:E5,0)) -> C
A6: 0.02 | B6: =(1-A6)/5 -> 0.196 | C6: =A6*Scores!D9+B6*(SUM(Scores!D6:D11)-Scores!D9) -> 59.72 | D6: =A6*Scores!E9+B6*(SUM(Scores!E6:E11)-Scores!E9) -> 36.66 | E6: =A6*Scores!F9+B6*(SUM(Scores!F6:F11)-Scores!F9) -> 63.036 | F6: =INDEX({"A","B","C"},MATCH(MAX(C6:E6),C6:E6,0)) -> C
A7: 0.04 | B7: =(1-A7)/5 -> 0.192 | C7: =A7*Scores!D9+B7*(SUM(Scores!D6:D11)-Scores!D9) -> 60.44 | D7: =A7*Scores!E9+B7*(SUM(Scores!E6:E11)-Scores!E9) -> 36.32 | E7: =A7*Scores!F9+B7*(SUM(Scores!F6:F11)-Scores!F9) -> 62.872 | F7: =INDEX({"A","B","C"},MATCH(MAX(C7:E7),C7:E7,0)) -> C
A8: 0.06 | B8: =(1-A8)/5 -> 0.188 | C8: =A8*Scores!D9+B8*(SUM(Scores!D6:D11)-Scores!D9) -> 61.16 | D8: =A8*Scores!E9+B8*(SUM(Scores!E6:E11)-Scores!E9) -> 35.98 | E8: =A8*Scores!F9+B8*(SUM(Scores!F6:F11)-Scores!F9) -> 62.708 | F8: =INDEX({"A","B","C"},MATCH(MAX(C8:E8),C8:E8,0)) -> C
A9: 0.08 | B9: =(1-A9)/5 -> 0.184 | C9: =A9*Scores!D9+B9*(SUM(Scores!D6:D11)-Scores!D9) -> 61.88 | D9: =A9*Scores!E9+B9*(SUM(Scores!E6:E11)-Scores!E9) -> 35.64 | E9: =A9*Scores!F9+B9*(SUM(Scores!F6:F11)-Scores!F9) -> 62.544 | F9: =INDEX({"A","B","C"},MATCH(MAX(C9:E9),C9:E9,0)) -> C
A10: 0.1 | B10: =(1-A10)/5 -> 0.18 | C10: =A10*Scores!D9+B10*(SUM(Scores!D6:D11)-Scores!D9) -> 62.6 | D10: =A10*Scores!E9+B10*(SUM(Scores!E6:E11)-Scores!E9) -> 35.3 | E10: =A10*Scores!F9+B10*(SUM(Scores!F6:F11)-Scores!F9) -> 62.38 | F10: =INDEX({"A","B","C"},MATCH(MAX(C10:E10),C10:E10,0)) -> A
A11: 0.12 | B11: =(1-A11)/5 -> 0.176 | C11: =A11*Scores!D9+B11*(SUM(Scores!D6:D11)-Scores!D9) -> 63.32 | D11: =A11*Scores!E9+B11*(SUM(Scores!E6:E11)-Scores!E9) -> 34.96 | E11: =A11*Scores!F9+B11*(SUM(Scores!F6:F11)-Scores!F9) -> 62.216 | F11: =INDEX({"A","B","C"},MATCH(MAX(C11:E11),C11:E11,0)) -> A
A12: 0.14 | B12: =(1-A12)/5 -> 0.172 | C12: =A12*Scores!D9+B12*(SUM(Scores!D6:D11)-Scores!D9) -> 64.04 | D12: =A12*Scores!E9+B12*(SUM(Scores!E6:E11)-Scores!E9) -> 34.62 | E12: =A12*Scores!F9+B12*(SUM(Scores!F6:F11)-Scores!F9) -> 62.052 | F12: =INDEX({"A","B","C"},MATCH(MAX(C12:E12),C12:E12,0)) -> A
A13: 0.16 | B13: =(1-A13)/5 -> 0.168 | C13: =A13*Scores!D9+B13*(SUM(Scores!D6:D11)-Scores!D9) -> 64.76 | D13: =A13*Scores!E9+B13*(SUM(Scores!E6:E11)-Scores!E9) -> 34.28 | E13: =A13*Scores!F9+B13*(SUM(Scores!F6:F11)-Scores!F9) -> 61.888 | F13: =INDEX({"A","B","C"},MATCH(MAX(C13:E13),C13:E13,0)) -> A
A14: 0.18 | B14: =(1-A14)/5 -> 0.164 | C14: =A14*Scores!D9+B14*(SUM(Scores!D6:D11)-Scores!D9) -> 65.48 | D14: =A14*Scores!E9+B14*(SUM(Scores!E6:E11)-Scores!E9) -> 33.94 | E14: =A14*Scores!F9+B14*(SUM(Scores!F6:F11)-Scores!F9) -> 61.724 | F14: =INDEX({"A","B","C"},MATCH(MAX(C14:E14),C14:E14,0)) -> A
A15: 0.2 | B15: =(1-A15)/5 -> 0.16 | C15: =A15*Scores!D9+B15*(SUM(Scores!D6:D11)-Scores!D9) -> 66.2 | D15: =A15*Scores!E9+B15*(SUM(Scores!E6:E11)-Scores!E9) -> 33.6 | E15: =A15*Scores!F9+B15*(SUM(Scores!F6:F11)-Scores!F9) -> 61.56 | F15: =INDEX({"A","B","C"},MATCH(MAX(C15:E15),C15:E15,0)) -> A
A16: 0.22 | B16: =(1-A16)/5 -> 0.156 | C16: =A16*Scores!D9+B16*(SUM(Scores!D6:D11)-Scores!D9) -> 66.92 | D16: =A16*Scores!E9+B16*(SUM(Scores!E6:E11)-Scores!E9) -> 33.26 | E16: =A16*Scores!F9+B16*(SUM(Scores!F6:F11)-Scores!F9) -> 61.396 | F16: =INDEX({"A","B","C"},MATCH(MAX(C16:E16),C16:E16,0)) -> A
A17: 0.24 | B17: =(1-A17)/5 -> 0.152 | C17: =A17*Scores!D9+B17*(SUM(Scores!D6:D11)-Scores!D9) -> 67.64 | D17: =A17*Scores!E9+B17*(SUM(Scores!E6:E11)-Scores!E9) -> 32.92 | E17: =A17*Scores!F9+B17*(SUM(Scores!F6:F11)-Scores!F9) -> 61.232 | F17: =INDEX({"A","B","C"},MATCH(MAX(C17:E17),C17:E17,0)) -> A
A18: 0.26 | B18: =(1-A18)/5 -> 0.148 | C18: =A18*Scores!D9+B18*(SUM(Scores!D6:D11)-Scores!D9) -> 68.36 | D18: =A18*Scores!E9+B18*(SUM(Scores!E6:E11)-Scores!E9) -> 32.58 | E18: =A18*Scores!F9+B18*(SUM(Scores!F6:F11)-Scores!F9) -> 61.068 | F18: =INDEX({"A","B","C"},MATCH(MAX(C18:E18),C18:E18,0)) -> A
A19: 0.28 | B19: =(1-A19)/5 -> 0.144 | C19: =A19*Scores!D9+B19*(SUM(Scores!D6:D11)-Scores!D9) -> 69.08 | D19: =A19*Scores!E9+B19*(SUM(Scores!E6:E11)-Scores!E9) -> 32.24 | E19: =A19*Scores!F9+B19*(SUM(Scores!F6:F11)-Scores!F9) -> 60.904 | F19: =INDEX({"A","B","C"},MATCH(MAX(C19:E19),C19:E19,0)) -> A
A20: 0.3 | B20: =(1-A20)/5 -> 0.14 | C20: =A20*Scores!D9+B20*(SUM(Scores!D6:D11)-Scores!D9) -> 69.8 | D20: =A20*Scores!E9+B20*(SUM(Scores!E6:E11)-Scores!E9) -> 31.9 | E20: =A20*Scores!F9+B20*(SUM(Scores!F6:F11)-Scores!F9) -> 60.74 | F20: =INDEX({"A","B","C"},MATCH(MAX(C20:E20),C20:E20,0)) -> A
A21: 0.32 | B21: =(1-A21)/5 -> 0.136 | C21: =A21*Scores!D9+B21*(SUM(Scores!D6:D11)-Scores!D9) -> 70.52 | D21: =A21*Scores!E9+B21*(SUM(Scores!E6:E11)-Scores!E9) -> 31.56 | E21: =A21*Scores!F9+B21*(SUM(Scores!F6:F11)-Scores!F9) -> 60.576 | F21: =INDEX({"A","B","C"},MATCH(MAX(C21:E21),C21:E21,0)) -> A
A22: 0.34 | B22: =(1-A22)/5 -> 0.132 | C22: =A22*Scores!D9+B22*(SUM(Scores!D6:D11)-Scores!D9) -> 71.24 | D22: =A22*Scores!E9+B22*(SUM(Scores!E6:E11)-Scores!E9) -> 31.22 | E22: =A22*Scores!F9+B22*(SUM(Scores!F6:F11)-Scores!F9) -> 60.412 | F22: =INDEX({"A","B","C"},MATCH(MAX(C22:E22),C22:E22,0)) -> A
A23: 0.36 | B23: =(1-A23)/5 -> 0.128 | C23: =A23*Scores!D9+B23*(SUM(Scores!D6:D11)-Scores!D9) -> 71.96 | D23: =A23*Scores!E9+B23*(SUM(Scores!E6:E11)-Scores!E9) -> 30.88 | E23: =A23*Scores!F9+B23*(SUM(Scores!F6:F11)-Scores!F9) -> 60.248 | F23: =INDEX({"A","B","C"},MATCH(MAX(C23:E23),C23:E23,0)) -> A
A24: 0.38 | B24: =(1-A24)/5 -> 0.124 | C24: =A24*Scores!D9+B24*(SUM(Scores!D6:D11)-Scores!D9) -> 72.68 | D24: =A24*Scores!E9+B24*(SUM(Scores!E6:E11)-Scores!E9) -> 30.54 | E24: =A24*Scores!F9+B24*(SUM(Scores!F6:F11)-Scores!F9) -> 60.084 | F24: =INDEX({"A","B","C"},MATCH(MAX(C24:E24),C24:E24,0)) -> A
A25: 0.4 | B25: =(1-A25)/5 -> 0.12 | C25: =A25*Scores!D9+B25*(SUM(Scores!D6:D11)-Scores!D9) -> 73.4 | D25: =A25*Scores!E9+B25*(SUM(Scores!E6:E11)-Scores!E9) -> 30.2 | E25: =A25*Scores!F9+B25*(SUM(Scores!F6:F11)-Scores!F9) -> 59.92 | F25: =INDEX({"A","B","C"},MATCH(MAX(C25:E25),C25:E25,0)) -> A
A26: 0.42 | B26: =(1-A26)/5 -> 0.116 | C26: =A26*Scores!D9+B26*(SUM(Scores!D6:D11)-Scores!D9) -> 74.12 | D26: =A26*Scores!E9+B26*(SUM(Scores!E6:E11)-Scores!E9) -> 29.86 | E26: =A26*Scores!F9+B26*(SUM(Scores!F6:F11)-Scores!F9) -> 59.756 | F26: =INDEX({"A","B","C"},MATCH(MAX(C26:E26),C26:E26,0)) -> A
A27: 0.44 | B27: =(1-A27)/5 -> 0.112 | C27: =A27*Scores!D9+B27*(SUM(Scores!D6:D11)-Scores!D9) -> 74.84 | D27: =A27*Scores!E9+B27*(SUM(Scores!E6:E11)-Scores!E9) -> 29.52 | E27: =A27*Scores!F9+B27*(SUM(Scores!F6:F11)-Scores!F9) -> 59.592 | F27: =INDEX({"A","B","C"},MATCH(MAX(C27:E27),C27:E27,0)) -> A
A28: 0.46 | B28: =(1-A28)/5 -> 0.108 | C28: =A28*Scores!D9+B28*(SUM(Scores!D6:D11)-Scores!D9) -> 75.56 | D28: =A28*Scores!E9+B28*(SUM(Scores!E6:E11)-Scores!E9) -> 29.18 | E28: =A28*Scores!F9+B28*(SUM(Scores!F6:F11)-Scores!F9) -> 59.428 | F28: =INDEX({"A","B","C"},MATCH(MAX(C28:E28),C28:E28,0)) -> A
A29: 0.48 | B29: =(1-A29)/5 -> 0.104 | C29: =A29*Scores!D9+B29*(SUM(Scores!D6:D11)-Scores!D9) -> 76.28 | D29: =A29*Scores!E9+B29*(SUM(Scores!E6:E11)-Scores!E9) -> 28.84 | E29: =A29*Scores!F9+B29*(SUM(Scores!F6:F11)-Scores!F9) -> 59.264 | F29: =INDEX({"A","B","C"},MATCH(MAX(C29:E29),C29:E29,0)) -> A
A30: 0.5 | B30: =(1-A30)/5 -> 0.1 | C30: =A30*Scores!D9+B30*(SUM(Scores!D6:D11)-Scores!D9) -> 77 | D30: =A30*Scores!E9+B30*(SUM(Scores!E6:E11)-Scores!E9) -> 28.5 | E30: =A30*Scores!F9+B30*(SUM(Scores!F6:F11)-Scores!F9) -> 59.1 | F30: =INDEX({"A","B","C"},MATCH(MAX(C30:E30),C30:E30,0)) -> A
A31: 0.52 | B31: =(1-A31)/5 -> 0.096 | C31: =A31*Scores!D9+B31*(SUM(Scores!D6:D11)-Scores!D9) -> 77.72 | D31: =A31*Scores!E9+B31*(SUM(Scores!E6:E11)-Scores!E9) -> 28.16 | E31: =A31*Scores!F9+B31*(SUM(Scores!F6:F11)-Scores!F9) -> 58.936 | F31: =INDEX({"A","B","C"},MATCH(MAX(C31:E31),C31:E31,0)) -> A
A32: 0.54 | B32: =(1-A32)/5 -> 0.092 | C32: =A32*Scores!D9+B32*(SUM(Scores!D6:D11)-Scores!D9) -> 78.44 | D32: =A32*Scores!E9+B32*(SUM(Scores!E6:E11)-Scores!E9) -> 27.82 | E32: =A32*Scores!F9+B32*(SUM(Scores!F6:F11)-Scores!F9) -> 58.772 | F32: =INDEX({"A","B","C"},MATCH(MAX(C32:E32),C32:E32,0)) -> A
A33: 0.56 | B33: =(1-A33)/5 -> 0.088 | C33: =A33*Scores!D9+B33*(SUM(Scores!D6:D11)-Scores!D9) -> 79.16 | D33: =A33*Scores!E9+B33*(SUM(Scores!E6:E11)-Scores!E9) -> 27.48 | E33: =A33*Scores!F9+B33*(SUM(Scores!F6:F11)-Scores!F9) -> 58.608 | F33: =INDEX({"A","B","C"},MATCH(MAX(C33:E33),C33:E33,0)) -> A
A34: 0.58 | B34: =(1-A34)/5 -> 0.084 | C34: =A34*Scores!D9+B34*(SUM(Scores!D6:D11)-Scores!D9) -> 79.88 | D34: =A34*Scores!E9+B34*(SUM(Scores!E6:E11)-Scores!E9) -> 27.14 | E34: =A34*Scores!F9+B34*(SUM(Scores!F6:F11)-Scores!F9) -> 58.444 | F34: =INDEX({"A","B","C"},MATCH(MAX(C34:E34),C34:E34,0)) -> A
A35: 0.6 | B35: =(1-A35)/5 -> 0.08 | C35: =A35*Scores!D9+B35*(SUM(Scores!D6:D11)-Scores!D9) -> 80.6 | D35: =A35*Scores!E9+B35*(SUM(Scores!E6:E11)-Scores!E9) -> 26.8 | E35: =A35*Scores!F9+B35*(SUM(Scores!F6:F11)-Scores!F9) -> 58.28 | F35: =INDEX({"A","B","C"},MATCH(MAX(C35:E35),C35:E35,0)) -> A
A36: 0.62 | B36: =(1-A36)/5 -> 0.076 | C36: =A36*Scores!D9+B36*(SUM(Scores!D6:D11)-Scores!D9) -> 81.32 | D36: =A36*Scores!E9+B36*(SUM(Scores!E6:E11)-Scores!E9) -> 26.46 | E36: =A36*Scores!F9+B36*(SUM(Scores!F6:F11)-Scores!F9) -> 58.116 | F36: =INDEX({"A","B","C"},MATCH(MAX(C36:E36),C36:E36,0)) -> A
A37: 0.64 | B37: =(1-A37)/5 -> 0.072 | C37: =A37*Scores!D9+B37*(SUM(Scores!D6:D11)-Scores!D9) -> 82.04 | D37: =A37*Scores!E9+B37*(SUM(Scores!E6:E11)-Scores!E9) -> 26.12 | E37: =A37*Scores!F9+B37*(SUM(Scores!F6:F11)-Scores!F9) -> 57.952 | F37: =INDEX({"A","B","C"},MATCH(MAX(C37:E37),C37:E37,0)) -> A
A38: 0.66 | B38: =(1-A38)/5 -> 0.068 | C38: =A38*Scores!D9+B38*(SUM(Scores!D6:D11)-Scores!D9) -> 82.76 | D38: =A38*Scores!E9+B38*(SUM(Scores!E6:E11)-Scores!E9) -> 25.78 | E38: =A38*Scores!F9+B38*(SUM(Scores!F6:F11)-Scores!F9) -> 57.788 | F38: =INDEX({"A","B","C"},MATCH(MAX(C38:E38),C38:E38,0)) -> A
A39: 0.68 | B39: =(1-A39)/5 -> 0.064 | C39: =A39*Scores!D9+B39*(SUM(Scores!D6:D11)-Scores!D9) -> 83.48 | D39: =A39*Scores!E9+B39*(SUM(Scores!E6:E11)-Scores!E9) -> 25.44 | E39: =A39*Scores!F9+B39*(SUM(Scores!F6:F11)-Scores!F9) -> 57.624 | F39: =INDEX({"A","B","C"},MATCH(MAX(C39:E39),C39:E39,0)) -> A
A40: 0.7 | B40: =(1-A40)/5 -> 0.06 | C40: =A40*Scores!D9+B40*(SUM(Scores!D6:D11)-Scores!D9) -> 84.2 | D40: =A40*Scores!E9+B40*(SUM(Scores!E6:E11)-Scores!E9) -> 25.1 | E40: =A40*Scores!F9+B40*(SUM(Scores!F6:F11)-Scores!F9) -> 57.46 | F40: =INDEX({"A","B","C"},MATCH(MAX(C40:E40),C40:E40,0)) -> A
A41: 0.72 | B41: =(1-A41)/5 -> 0.056 | C41: =A41*Scores!D9+B41*(SUM(Scores!D6:D11)-Scores!D9) -> 84.92 | D41: =A41*Scores!E9+B41*(SUM(Scores!E6:E11)-Scores!E9) -> 24.76 | E41: =A41*Scores!F9+B41*(SUM(Scores!F6:F11)-Scores!F9) -> 57.296 | F41: =INDEX({"A","B","C"},MATCH(MAX(C41:E41),C41:E41,0)) -> A
...

Sheet Sensitivity_C5
A1: One-way Sensitivity: Weight on C5: Reversibility (T=5)
A2: Sweep w(C5) from 0→1. Other 5 weights = (1-w)/5 each. Closed-form thresholds at bottom.
A4: w(C5) | B4: Other(each) | C4: Option A | D4: Option B | E4: Option C | F4: Leader
A5: 0 | B5: =(1-A5)/5 -> 0.2 | C5: =A5*Scores!D10+B5*(SUM(Scores!D6:D11)-Scores!D10) -> 59 | D5: =A5*Scores!E10+B5*(SUM(Scores!E6:E11)-Scores!E10) -> 39 | E5: =A5*Scores!F10+B5*(SUM(Scores!F6:F11)-Scores!F10) -> 59.2 | F5: =INDEX({"A","B","C"},MATCH(MAX(C5:E5),C5:E5,0)) -> C
A6: 0.02 | B6: =(1-A6)/5 -> 0.196 | C6: =A6*Scores!D10+B6*(SUM(Scores!D6:D11)-Scores!D10) -> 59.72 | D6: =A6*Scores!E10+B6*(SUM(Scores!E6:E11)-Scores!E10) -> 38.42 | E6: =A6*Scores!F10+B6*(SUM(Scores!F6:F11)-Scores!F10) -> 59.516 | F6: =INDEX({"A","B","C"},MATCH(MAX(C6:E6),C6:E6,0)) -> A
A7: 0.04 | B7: =(1-A7)/5 -> 0.192 | C7: =A7*Scores!D10+B7*(SUM(Scores!D6:D11)-Scores!D10) -> 60.44 | D7: =A7*Scores!E10+B7*(SUM(Scores!E6:E11)-Scores!E10) -> 37.84 | E7: =A7*Scores!F10+B7*(SUM(Scores!F6:F11)-Scores!F10) -> 59.832 | F7: =INDEX({"A","B","C"},MATCH(MAX(C7:E7),C7:E7,0)) -> A
A8: 0.06 | B8: =(1-A8)/5 -> 0.188 | C8: =A8*Scores!D10+B8*(SUM(Scores!D6:D11)-Scores!D10) -> 61.16 | D8: =A8*Scores!E10+B8*(SUM(Scores!E6:E11)-Scores!E10) -> 37.26 | E8: =A8*Scores!F10+B8*(SUM(Scores!F6:F11)-Scores!F10) -> 60.148 | F8: =INDEX({"A","B","C"},MATCH(MAX(C8:E8),C8:E8,0)) -> A
A9: 0.08 | B9: =(1-A9)/5 -> 0.184 | C9: =A9*Scores!D10+B9*(SUM(Scores!D6:D11)-Scores!D10) -> 61.88 | D9: =A9*Scores!E10+B9*(SUM(Scores!E6:E11)-Scores!E10) -> 36.68 | E9: =A9*Scores!F10+B9*(SUM(Scores!F6:F11)-Scores!F10) -> 60.464 | F9: =INDEX({"A","B","C"},MATCH(MAX(C9:E9),C9:E9,0)) -> A
A10: 0.1 | B10: =(1-A10)/5 -> 0.18 | C10: =A10*Scores!D10+B10*(SUM(Scores!D6:D11)-Scores!D10) -> 62.6 | D10: =A10*Scores!E10+B10*(SUM(Scores!E6:E11)-Scores!E10) -> 36.1 | E10: =A10*Scores!F10+B10*(SUM(Scores!F6:F11)-Scores!F10) -> 60.78 | F10: =INDEX({"A","B","C"},MATCH(MAX(C10:E10),C10:E10,0)) -> A
A11: 0.12 | B11: =(1-A11)/5 -> 0.176 | C11: =A11*Scores!D10+B11*(SUM(Scores!D6:D11)-Scores!D10) -> 63.32 | D11: =A11*Scores!E10+B11*(SUM(Scores!E6:E11)-Scores!E10) -> 35.52 | E11: =A11*Scores!F10+B11*(SUM(Scores!F6:F11)-Scores!F10) -> 61.096 | F11: =INDEX({"A","B","C"},MATCH(MAX(C11:E11),C11:E11,0)) -> A
A12: 0.14 | B12: =(1-A12)/5 -> 0.172 | C12: =A12*Scores!D10+B12*(SUM(Scores!D6:D11)-Scores!D10) -> 64.04 | D12: =A12*Scores!E10+B12*(SUM(Scores!E6:E11)-Scores!E10) -> 34.94 | E12: =A12*Scores!F10+B12*(SUM(Scores!F6:F11)-Scores!F10) -> 61.412 | F12: =INDEX({"A","B","C"},MATCH(MAX(C12:E12),C12:E12,0)) -> A
A13: 0.16 | B13: =(1-A13)/5 -> 0.168 | C13: =A13*Scores!D10+B13*(SUM(Scores!D6:D11)-Scores!D10) -> 64.76 | D13: =A13*Scores!E10+B13*(SUM(Scores!E6:E11)-Scores!E10) -> 34.36 | E13: =A13*Scores!F10+B13*(SUM(Scores!F6:F11)-Scores!F10) -> 61.728 | F13: =INDEX({"A","B","C"},MATCH(MAX(C13:E13),C13:E13,0)) -> A
A14: 0.18 | B14: =(1-A14)/5 -> 0.164 | C14: =A14*Scores!D10+B14*(SUM(Scores!D6:D11)-Scores!D10) -> 65.48 | D14: =A14*Scores!E10+B14*(SUM(Scores!E6:E11)-Scores!E10) -> 33.78 | E14: =A14*Scores!F10+B14*(SUM(Scores!F6:F11)-Scores!F10) -> 62.044 | F14: =INDEX({"A","B","C"},MATCH(MAX(C14:E14),C14:E14,0)) -> A
A15: 0.2 | B15: =(1-A15)/5 -> 0.16 | C15: =A15*Scores!D10+B15*(SUM(Scores!D6:D11)-Scores!D10) -> 66.2 | D15: =A15*Scores!E10+B15*(SUM(Scores!E6:E11)-Scores!E10) -> 33.2 | E15: =A15*Scores!F10+B15*(SUM(Scores!F6:F11)-Scores!F10) -> 62.36 | F15: =INDEX({"A","B","C"},MATCH(MAX(C15:E15),C15:E15,0)) -> A
A16: 0.22 | B16: =(1-A16)/5 -> 0.156 | C16: =A16*Scores!D10+B16*(SUM(Scores!D6:D11)-Scores!D10) -> 66.92 | D16: =A16*Scores!E10+B16*(SUM(Scores!E6:E11)-Scores!E10) -> 32.62 | E16: =A16*Scores!F10+B16*(SUM(Scores!F6:F11)-Scores!F10) -> 62.676 | F16: =INDEX({"A","B","C"},MATCH(MAX(C16:E16),C16:E16,0)) -> A
A17: 0.24 | B17: =(1-A17)/5 -> 0.152 | C17: =A17*Scores!D10+B17*(SUM(Scores!D6:D11)-Scores!D10) -> 67.64 | D17: =A17*Scores!E10+B17*(SUM(Scores!E6:E11)-Scores!E10) -> 32.04 | E17: =A17*Scores!F10+B17*(SUM(Scores!F6:F11)-Scores!F10) -> 62.992 | F17: =INDEX({"A","B","C"},MATCH(MAX(C17:E17),C17:E17,0)) -> A
A18: 0.26 | B18: =(1-A18)/5 -> 0.148 | C18: =A18*Scores!D10+B18*(SUM(Scores!D6:D11)-Scores!D10) -> 68.36 | D18: =A18*Scores!E10+B18*(SUM(Scores!E6:E11)-Scores!E10) -> 31.46 | E18: =A18*Scores!F10+B18*(SUM(Scores!F6:F11)-Scores!F10) -> 63.308 | F18: =INDEX({"A","B","C"},MATCH(MAX(C18:E18),C18:E18,0)) -> A
A19: 0.28 | B19: =(1-A19)/5 -> 0.144 | C19: =A19*Scores!D10+B19*(SUM(Scores!D6:D11)-Scores!D10) -> 69.08 | D19: =A19*Scores!E10+B19*(SUM(Scores!E6:E11)-Scores!E10) -> 30.88 | E19: =A19*Scores!F10+B19*(SUM(Scores!F6:F11)-Scores!F10) -> 63.624 | F19: =INDEX({"A","B","C"},MATCH(MAX(C19:E19),C19:E19,0)) -> A
A20: 0.3 | B20: =(1-A20)/5 -> 0.14 | C20: =A20*Scores!D10+B20*(SUM(Scores!D6:D11)-Scores!D10) -> 69.8 | D20: =A20*Scores!E10+B20*(SUM(Scores!E6:E11)-Scores!E10) -> 30.3 | E20: =A20*Scores!F10+B20*(SUM(Scores!F6:F11)-Scores!F10) -> 63.94 | F20: =INDEX({"A","B","C"},MATCH(MAX(C20:E20),C20:E20,0)) -> A
A21: 0.32 | B21: =(1-A21)/5 -> 0.136 | C21: =A21*Scores!D10+B21*(SUM(Scores!D6:D11)-Scores!D10) -> 70.52 | D21: =A21*Scores!E10+B21*(SUM(Scores!E6:E11)-Scores!E10) -> 29.72 | E21: =A21*Scores!F10+B21*(SUM(Scores!F6:F11)-Scores!F10) -> 64.256 | F21: =INDEX({"A","B","C"},MATCH(MAX(C21:E21),C21:E21,0)) -> A
A22: 0.34 | B22: =(1-A22)/5 -> 0.132 | C22: =A22*Scores!D10+B22*(SUM(Scores!D6:D11)-Scores!D10) -> 71.24 | D22: =A22*Scores!E10+B22*(SUM(Scores!E6:E11)-Scores!E10) -> 29.14 | E22: =A22*Scores!F10+B22*(SUM(Scores!F6:F11)-Scores!F10) -> 64.572 | F22: =INDEX({"A","B","C"},MATCH(MAX(C22:E22),C22:E22,0)) -> A
A23: 0.36 | B23: =(1-A23)/5 -> 0.128 | C23: =A23*Scores!D10+B23*(SUM(Scores!D6:D11)-Scores!D10) -> 71.96 | D23: =A23*Scores!E10+B23*(SUM(Scores!E6:E11)-Scores!E10) -> 28.56 | E23: =A23*Scores!F10+B23*(SUM(Scores!F6:F11)-Scores!F10) -> 64.888 | F23: =INDEX({"A","B","C"},MATCH(MAX(C23:E23),C23:E23,0)) -> A
A24: 0.38 | B24: =(1-A24)/5 -> 0.124 | C24: =A24*Scores!D10+B24*(SUM(Scores!D6:D11)-Scores!D10) -> 72.68 | D24: =A24*Scores!E10+B24*(SUM(Scores!E6:E11)-Scores!E10) -> 27.98 | E24: =A24*Scores!F10+B24*(SUM(Scores!F6:F11)-Scores!F10) -> 65.204 | F24: =INDEX({"A","B","C"},MATCH(MAX(C24:E24),C24:E24,0)) -> A
A25: 0.4 | B25: =(1-A25)/5 -> 0.12 | C25: =A25*Scores!D10+B25*(SUM(Scores!D6:D11)-Scores!D10) -> 73.4 | D25: =A25*Scores!E10+B25*(SUM(Scores!E6:E11)-Scores!E10) -> 27.4 | E25: =A25*Scores!F10+B25*(SUM(Scores!F6:F11)-Scores!F10) -> 65.52 | F25: =INDEX({"A","B","C"},MATCH(MAX(C25:E25),C25:E25,0)) -> A
A26: 0.42 | B26: =(1-A26)/5 -> 0.116 | C26: =A26*Scores!D10+B26*(SUM(Scores!D6:D11)-Scores!D10) -> 74.12 | D26: =A26*Scores!E10+B26*(SUM(Scores!E6:E11)-Scores!E10) -> 26.82 | E26: =A26*Scores!F10+B26*(SUM(Scores!F6:F11)-Scores!F10) -> 65.836 | F26: =INDEX({"A","B","C"},MATCH(MAX(C26:E26),C26:E26,0)) -> A
A27: 0.44 | B27: =(1-A27)/5 -> 0.112 | C27: =A27*Scores!D10+B27*(SUM(Scores!D6:D11)-Scores!D10) -> 74.84 | D27: =A27*Scores!E10+B27*(SUM(Scores!E6:E11)-Scores!E10) -> 26.24 | E27: =A27*Scores!F10+B27*(SUM(Scores!F6:F11)-Scores!F10) -> 66.152 | F27: =INDEX({"A","B","C"},MATCH(MAX(C27:E27),C27:E27,0)) -> A
A28: 0.46 | B28: =(1-A28)/5 -> 0.108 | C28: =A28*Scores!D10+B28*(SUM(Scores!D6:D11)-Scores!D10) -> 75.56 | D28: =A28*Scores!E10+B28*(SUM(Scores!E6:E11)-Scores!E10) -> 25.66 | E28: =A28*Scores!F10+B28*(SUM(Scores!F6:F11)-Scores!F10) -> 66.468 | F28: =INDEX({"A","B","C"},MATCH(MAX(C28:E28),C28:E28,0)) -> A
A29: 0.48 | B29: =(1-A29)/5 -> 0.104 | C29: =A29*Scores!D10+B29*(SUM(Scores!D6:D11)-Scores!D10) -> 76.28 | D29: =A29*Scores!E10+B29*(SUM(Scores!E6:E11)-Scores!E10) -> 25.08 | E29: =A29*Scores!F10+B29*(SUM(Scores!F6:F11)-Scores!F10) -> 66.784 | F29: =INDEX({"A","B","C"},MATCH(MAX(C29:E29),C29:E29,0)) -> A
A30: 0.5 | B30: =(1-A30)/5 -> 0.1 | C30: =A30*Scores!D10+B30*(SUM(Scores!D6:D11)-Scores!D10) -> 77 | D30: =A30*Scores!E10+B30*(SUM(Scores!E6:E11)-Scores!E10) -> 24.5 | E30: =A30*Scores!F10+B30*(SUM(Scores!F6:F11)-Scores!F10) -> 67.1 | F30: =INDEX({"A","B","C"},MATCH(MAX(C30:E30),C30:E30,0)) -> A
A31: 0.52 | B31: =(1-A31)/5 -> 0.096 | C31: =A31*Scores!D10+B31*(SUM(Scores!D6:D11)-Scores!D10) -> 77.72 | D31: =A31*Scores!E10+B31*(SUM(Scores!E6:E11)-Scores!E10) -> 23.92 | E31: =A31*Scores!F10+B31*(SUM(Scores!F6:F11)-Scores!F10) -> 67.416 | F31: =INDEX({"A","B","C"},MATCH(MAX(C31:E31),C31:E31,0)) -> A
